Workbook

Sheet GP Main
A2: जल गंगा अभियान का नवीन डैशबोर्ड- GP वार नरेगा स्‍कीम - जिला पंचायत सतना 15-05-2026
A5: क्रमांक | B5: जनपद | C5: क्लस्टर | D5: ग्राम पंचायत | E5: उपयंत्री | F5: सहायक यंत्री | G5: Total Ongoing | H5: Total Completed | I5: Farm Pond | K5: Dug Well Recharge | M5: Water conservation & recharge | O5: Repair & Maintenance (Water Structures) | Q5: Watershed Related Works | S5: Irrigation infrastructure | U5: Amrit Sarowar | W5: Gap Filling in Plantation
I6: Ongoing | J6: Completed | K6: Ongoing | L6: Completed | M6: Ongoing | N6: Completed | O6: Ongoing | P6: Completed | Q6: Ongoing | R6: Completed | S6: Ongoing | T6: Completed | U6: Ongoing | V6: Completed | W6: Ongoing | X6: Completed
A8: 1 | B8: AMARPATAN | C8: RAMGARH | D8: AHIRGAON | E8: श्रीमती साधना चौरे | F8: भूपेन्द्र सिंह अति0 | G8: 25 | H8: 0 | I8: 20 | J8: 0 | K8: 3 | L8: 0 | M8: 1 | N8: 0 | O8: 0 | P8: 0 | Q8: 0 | R8: 0 | S8: 1 | T8: 0 | U8: 0 | V8: 0 | W8: =COUNTIFS(Work!$D$3:$D$5800,'CFT Main'!$B8,Work!$N$3:$N$5800,'CFT Main'!$C8,Work!$G$3:$G$5800,"Ongoing",Work!$F$3:$F$5800,W$5) -> 35 | X8: =COUNTIFS(Work!$D$3:$D$5800,'CFT Main'!$B8,Work!$N$3:$N$5800,'CFT Main'!$C8,Work!$G$3:$G$5800,"*Completed",Work!$F$3:$F$5800,W$5) -> 0
A9: 2 | B9: AMARPATAN | C9: TALA | D9: AMIN | E9: सत्यनारायण मिश्रा | F9: भूपेन्द्र सिंह अति0 | G9: 22 | H9: 0 | I9: 9 | J9: 0 | K9: 9 | L9: 0 | M9: 4 | N9: 0 | O9: 0 | P9: 0 | Q9: 0 | R9: 0 | S9: 0 | T9: 0 | U9: 0 | V9: 0 | W9: =COUNTIFS(Work!$D$3:$D$5800,'CFT Main'!$B9,Work!$N$3:$N$5800,'CFT Main'!$C9,Work!$G$3:$G$5800,"Ongoing",Work!$F$3:$F$5800,W$5) -> 40 | X9: =COUNTIFS(Work!$D$3:$D$5800,'CFT Main'!$B9,Work!$N$3:$N$5800,'CFT Main'!$C9,Work!$G$3:$G$5800,"*Completed",Work!$F$3:$F$5800,W$5) -> 0
A10: 3 | B10: AMARPATAN | C10: RAMGARH | D10: AMJHAR | E10: श्रीमती साधना चौरे | F10: भूपेन्द्र सिंह अति0 | G10: 21 | H10: 0 | I10: 3 | J10: 0 | K10: 16 | L10: 0 | M10: 1 | N10: 0 | O10: 0 | P10: 0 | Q10: 0 | R10: 0 | S10: 1 | T10: 0 | U10: 0 | V10: 0 | W10: =COUNTIFS(Work!$D$3:$D$5800,'CFT Main'!$B10,Work!$N$3:$N$5800,'CFT Main'!$C10,Work!$G$3:$G$5800,"Ongoing",Work!$F$3:$F$5800,W$5) -> 25 | X10: =COUNTIFS(Work!$D$3:$D$5800,'CFT Main'!$B10,Work!$N$3:$N$5800,'CFT Main'!$C10,Work!$G$3:$G$5800,"*Completed",Work!$F$3:$F$5800,W$5) -> 0
A11: 4 | B11: AMARPATAN | C11: TALA | D11: ANANDGARH | E11: सत्यनारायण मिश्रा | F11: भूपेन्द्र सिंह अति0 | G11: 20 | H11: 3 | I11: 20 | J11: 1 | K11: 0 | L11: 2 | M11: 0 | N11: 0 | O11: 0 | P11: 0 | Q11: 0 | R11: 0 | S11: 0 | T11: 0 | U11: 0 | V11: 0 | W11: =COUNTIFS(Work!$D$3:$D$5800,'CFT Main'!$B11,Work!$N$3:$N$5800,'CFT Main'!$C11,Work!$G$3:$G$5800,"Ongoing",Work!$F$3:$F$5800,W$5) -> 34 | X11: =COUNTIFS(Work!$D$3:$D$5800,'CFT Main'!$B11,Work!$N$3:$N$5800,'CFT Main'!$C11,Work!$G$3:$G$5800,"*Completed",Work!$F$3:$F$5800,W$5) -> 0
A12: 5 | B12: AMARPATAN | C12: RAMGARH | D12: BACHHARA | E12: श्रीमती साधना चौरे | F12: भूपेन्द्र सिंह अति0 | G12: 18 | H12: 2 | I12: 10 | J12: 1 | K12: 4 | L12: 0 | M12: 3 | N12: 1 | O12: 1 | P12: 0 | Q12: 0 | R12: 0 | S12: 0 | T12: 0 | U12: 0 | V12: 0 | W12: =COUNTIFS(Work!$D$3:$D$5800,'CFT Main'!$B12,Work!$N$3:$N$5800,'CFT Main'!$C12,Work!$G$3:$G$5800,"Ongoing",Work!$F$3:$F$5800,W$5) -> 37 | X12: =COUNTIFS(Work!$D$3:$D$5800,'CFT Main'!$B12,Work!$N$3:$N$5800,'CFT Main'!$C12,Work!$G$3:$G$5800,"*Completed",Work!$F$3:$F$5800,W$5) -> 0
A13: 6 | B13: AMARPATAN | C13: LALPUR | D13: BARREHBADA | E13: अश्वनी पटेल | F13: भूपेन्द्र सिंह अति0 | G13: 16 | H13: 0 | I13: 12 | J13: 0 | K13: 0 | L13: 0 | M13: 2 | N13: 0 | O13: 1 | P13: 0 | Q13: 0 | R13: 0 | S13: 1 | T13: 0 | U13: 0 | V13: 0 | W13: =COUNTIFS(Work!$D$3:$D$5800,'CFT Main'!$B13,Work!$N$3:$N$5800,'CFT Main'!$C13,Work!$G$3:$G$5800,"Ongoing",Work!$F$3:$F$5800,W$5) -> 8 | X13: =COUNTIFS(Work!$D$3:$D$5800,'CFT Main'!$B13,Work!$N$3:$N$5800,'CFT Main'!$C13,Work!$G$3:$G$5800,"*Completed",Work!$F$3:$F$5800,W$5) -> 0
A14: 7 | B14: AMARPATAN | C14: BELA | D14: BELA | E14: सुनील मिश्रा | F14: भूपेन्द्र सिंह अति0 | G14: 16 | H14: 0 | I14: 12 | J14: 0 | K14: 0 | L14: 0 | M14: 1 | N14: 0 | O14: 2 | P14: 0 | Q14: 1 | R14: 0 | S14: 0 | T14: 0 | U14: 0 | V14: 0 | W14: =COUNTIFS(Work!$D$3:$D$5800,'CFT Main'!$B14,Work!$N$3:$N$5800,'CFT Main'!$C14,Work!$G$3:$G$5800,"Ongoing",Work!$F$3:$F$5800,W$5) -> 30 | X14: =COUNTIFS(Work!$D$3:$D$5800,'CFT Main'!$B14,Work!$N$3:$N$5800,'CFT Main'!$C14,Work!$G$3:$G$5800,"*Completed",Work!$F$3:$F$5800,W$5) -> 0
A15: 8 | B15: AMARPATAN | C15: RAMGARH | D15: BHADRA | E15: श्रीमती साधना चौरे | F15: भूपेन्द्र सिंह अति0 | G15: 16 | H15: 0 | I15: 10 | J15: 0 | K15: 0 | L15: 0 | M15: 4 | N15: 0 | O15: 0 | P15: 0 | Q15: 0 | R15: 0 | S15: 2 | T15: 0 | U15: 0 | V15: 0 | W15: =COUNTIFS(Work!$D$3:$D$5800,'CFT Main'!$B15,Work!$N$3:$N$5800,'CFT Main'!$C15,Work!$G$3:$G$5800,"Ongoing",Work!$F$3:$F$5800,W$5) -> 15 | X15: =COUNTIFS(Work!$D$3:$D$5800,'CFT Main'!$B15,Work!$N$3:$N$5800,'CFT Main'!$C15,Work!$G$3:$G$5800,"*Completed",Work!$F$3:$F$5800,W$5) -> 0
A16: 9 | B16: AMARPATAN | C16: TALA | D16: BHADWA | E16: सत्यनारायण मिश्रा | F16: भूपेन्द्र सिंह अति0 | G16: 16 | H16: 0 | I16: 9 | J16: 0 | K16: 4 | L16: 0 | M16: 3 | N16: 0 | O16: 0 | P16: 0 | Q16: 0 | R16: 0 | S16: 0 | T16: 0 | U16: 0 | V16: 0 | W16: =COUNTIFS(Work!$D$3:$D$5800,'CFT Main'!$B16,Work!$N$3:$N$5800,'CFT Main'!$C16,Work!$G$3:$G$5800,"Ongoing",Work!$F$3:$F$5800,W$5) -> 9 | X16: =COUNTIFS(Work!$D$3:$D$5800,'CFT Main'!$B16,Work!$N$3:$N$5800,'CFT Main'!$C16,Work!$G$3:$G$5800,"*Completed",Work!$F$3:$F$5800,W$5) -> 0
A17: 10 | B17: AMARPATAN | C17: RAMGARH | D17: BHICHHIYAKHURD | E17: श्रीमती साधना चौरे | F17: भूपेन्द्र सिंह अति0 | G17: 14 | H17: 8 | I17: 13 | J17: 3 | K17: 0 | L17: 4 | M17: 1 | N17: 1 | O17: 0 | P17: 0 | Q17: 0 | R17: 0 | S17: 0 | T17: 0 | U17: 0 | V17: 0 | W17: =COUNTIFS(Work!$D$3:$D$5800,'CFT Main'!$B17,Work!$N$3:$N$5800,'CFT Main'!$C17,Work!$G$3:$G$5800,"Ongoing",Work!$F$3:$F$5800,W$5) -> 8 | X17: =COUNTIFS(Work!$D$3:$D$5800,'CFT Main'!$B17,Work!$N$3:$N$5800,'CFT Main'!$C17,Work!$G$3:$G$5800,"*Completed",Work!$F$3:$F$5800,W$5) -> 0
A18: 11 | B18: AMARPATAN | C18: LALPUR | D18: BHISHAMPUR | E18: अश्वनी पटेल | F18: भूपेन्द्र सिंह अति0 | G18: 13 | H18: 1 | I18: 7 | J18: 1 | K18: 0 | L18: 0 | M18: 4 | N18: 0 | O18: 1 | P18: 0 | Q18: 1 | R18: 0 | S18: 0 | T18: 0 | U18: 0 | V18: 0 | W18: =COUNTIFS(Work!$D$3:$D$5800,'CFT Main'!$B18,Work!$N$3:$N$5800,'CFT Main'!$C18,Work!$G$3:$G$5800,"Ongoing",Work!$F$3:$F$5800,W$5) -> 12 | X18: =COUNTIFS(Work!$D$3:$D$5800,'CFT Main'!$B18,Work!$N$3:$N$5800,'CFT Main'!$C18,Work!$G$3:$G$5800,"*Completed",Work!$F$3:$F$5800,W$5) -> 0
A19: 12 | B19: AMARPATAN | C19: RAMGARH | D19: BIDHUIKHURD | E19: श्रीमती साधना चौरे | F19: भूपेन्द्र सिंह अति0 | G19: 12 | H19: 7 | I19: 10 | J19: 6 | K19: 0 | L19: 1 | M19: 1 | N19: 0 | O19: 0 | P19: 0 | Q19: 1 | R19: 0 | S19: 0 | T19: 0 | U19: 0 | V19: 0 | W19: =COUNTIFS(Work!$D$3:$D$5800,'CFT Main'!$B19,Work!$N$3:$N$5800,'CFT Main'!$C19,Work!$G$3:$G$5800,"Ongoing",Work!$F$3:$F$5800,W$5) -> 19 | X19: =COUNTIFS(Work!$D$3:$D$5800,'CFT Main'!$B19,Work!$N$3:$N$5800,'CFT Main'!$C19,Work!$G$3:$G$5800,"*Completed",Work!$F$3:$F$5800,W$5) -> 0
... A44: 37 | B44: AMARPATAN | C44: MAUHARI KATARA | D44: KHUTAHA | E44: अनिल पटेल | F44: भूपेन्द्र सिंह अति0 | G44: 9 | H44: 0 | I44: 5 | J44: 0 | K44: 0 | L44: 0 | M44: 2 | N44: 0 | O44: 2 | P44: 0 | Q44: 0 | R44: 0 | S44: 0 | T44: 0 | U44: 0 | V44: 0 | W44: =COUNTIFS(Work!$D$3:$D$5800,'CFT Main'!$B44,Work!$N$3:$N$5800,'CFT Main'!$C44,Work!$G$3:$G$5800,"Ongoing",Work!$F$3:$F$5800,W$5) -> 14 | X44: =COUNTIFS(Work!$D$3:$D$5800,'CFT Main'!$B44,Work!$N$3:$N$5800,'CFT Main'!$C44,Work!$G$3:$G$5800,"*Completed",Work!$F$3:$F$5800,W$5) -> 1
A45: 38 | B45: AMARPATAN | C45: LALPUR | D45: KIRHAI | E45: अश्वनी पटेल | F45: भूपेन्द्र सिंह अति0 | G45: 9 | H45: 0 | I45: 4 | J45: 0 | K45: 2 | L45: 0 | M45: 2 | N45: 0 | O45: 1 | P45: 0 | Q45: 0 | R45: 0 | S45: 0 | T45: 0 | U45: 0 | V45: 0 | W45: =COUNTIFS(Work!$D$3:$D$5800,'CFT Main'!$B46,Work!$N$3:$N$5800,'CFT Main'!$C46,Work!$G$3:$G$5800,"Ongoing",Work!$F$3:$F$5800,W$5) -> 18 | X45: =COUNTIFS(Work!$D$3:$D$5800,'CFT Main'!$B46,Work!$N$3:$N$5800,'CFT Main'!$C46,Work!$G$3:$G$5800,"*Completed",Work!$F$3:$F$5800,W$5) -> 0
A46: 39 | B46: AMARPATAN | C46: MAUHARI KATARA | D46: KORIGAWAN | E46: अनिल पटेल | F46: भूपेन्द्र सिंह अति0 | G46: 9 | H46: 0 | I46: 4 | J46: 0 | K46: 0 | L46: 0 | M46: 4 | N46: 0 | O46: 1 | P46: 0 | Q46: 0 | R46: 0 | S46: 0 | T46: 0 | U46: 0 | V46: 0 | W46: =COUNTIFS(Work!$D$3:$D$5800,'CFT Main'!$B47,Work!$N$3:$N$5800,'CFT Main'!$C47,Work!$G$3:$G$5800,"Ongoing",Work!$F$3:$F$5800,W$5) -> 7 | X46: =COUNTIFS(Work!$D$3:$D$5800,'CFT Main'!$B47,Work!$N$3:$N$5800,'CFT Main'!$C47,Work!$G$3:$G$5800,"*Completed",Work!$F$3:$F$5800,W$5) -> 0
A47: 40 | B47: AMARPATAN | C47: TALA | D47: KOTAR | E47: सत्यनारायण मिश्रा | F47: भूपेन्द्र सिंह अति0 | G47: 9 | H47: 2 | I47: 2 | J47: 2 | K47: 6 | L47: 0 | M47: 1 | N47: 0 | O47: 0 | P47: 0 | Q47: 0 | R47: 0 | S47: 0 | T47: 0 | U47: 0 | V47: 0 | W47: =COUNTIFS(Work!$D$3:$D$5800,'CFT Main'!$B48,Work!$N$3:$N$5800,'CFT Main'!$C48,Work!$G$3:$G$5800,"Ongoing",Work!$F$3:$F$5800,W$5) -> 17 | X47: =COUNTIFS(Work!$D$3:$D$5800,'CFT Main'!$B48,Work!$N$3:$N$5800,'CFT Main'!$C48,Work!$G$3:$G$5800,"*Completed",Work!$F$3:$F$5800,W$5) -> 0
A48: 41 | B48: AMARPATAN | C48: LALPUR | D48: KUMHARI | E48: अश्वनी पटेल | F48: भूपेन्द्र सिंह अति0 | G48: 9 | H48: 2 | I48: 1 | J48: 0 | K48: 2 | L48: 0 | M48: 6 | N48: 2 | O48: 0 | P48: 0 | Q48: 0 | R48: 0 | S48: 0 | T48: 0 | U48: 0 | V48: 0 | W48: =COUNTIFS(Work!$D$3:$D$5800,'CFT Main'!$B49,Work!$N$3:$N$5800,'CFT Main'!$C49,Work!$G$3:$G$5800,"Ongoing",Work!$F$3:$F$5800,W$5) -> 17 | X48: =COUNTIFS(Work!$D$3:$D$5800,'CFT Main'!$B49,Work!$N$3:$N$5800,'CFT Main'!$C49,Work!$G$3:$G$5800,"*Completed",Work!$F$3:$F$5800,W$5) -> 2
A49: 42 | B49: AMARPATAN | C49: TALA | D49: LALITPURNOTWO | E49: सत्यनारायण मिश्रा | F49: भूपेन्द्र सिंह अति0 | G49: 8 | H49: 0 | I49: 8 | J49: 0 | K49: 0 | L49: 0 | M49: 0 | N49: 0 | O49: 0 | P49: 0 | Q49: 0 | R49: 0 | S49: 0 | T49: 0 | U49: 0 | V49: 0 | W49: =COUNTIFS(Work!$D$3:$D$5800,'CFT Main'!$B50,Work!$N$3:$N$5800,'CFT Main'!$C50,Work!$G$3:$G$5800,"Ongoing",Work!$F$3:$F$5800,W$5) -> 17 | X49: =COUNTIFS(Work!$D$3:$D$5800,'CFT Main'!$B50,Work!$N$3:$N$5800,'CFT Main'!$C50,Work!$G$3:$G$5800,"*Completed",Work!$F$3:$F$5800,W$5) -> 0
A50: 43 | B50: AMARPATAN | C50: LALPUR | D50: LALPUR | E50: अश्वनी पटेल | F50: भूपेन्द्र सिंह अति0 | G50: 8 | H50: 0 | I50: 7 | J50: 0 | K50: 0 | L50: 0 | M50: 1 | N50: 0 | O50: 0 | P50: 0 | Q50: 0 | R50: 0 | S50: 0 | T50: 0 | U50: 0 | V50: 0 | W50: =COUNTIFS(Work!$D$3:$D$5800,'CFT Main'!$B51,Work!$N$3:$N$5800,'CFT Main'!$C51,Work!$G$3:$G$5800,"Ongoing",Work!$F$3:$F$5800,W$5) -> 30 | X50: =COUNTIFS(Work!$D$3:$D$5800,'CFT Main'!$B51,Work!$N$3:$N$5800,'CFT Main'!$C51,Work!$G$3:$G$5800,"*Completed",Work!$F$3:$F$5800,W$5) -> 0
A51: 44 | B51: AMARPATAN | C51: BELA | D51: MADHA | E51: सुनील मिश्रा | F51: भूपेन्द्र सिंह अति0 | G51: 8 | H51: 1 | I51: 6 | J51: 0 | K51: 1 | L51: 0 | M51: 1 | N51: 1 | O51: 0 | P51: 0 | Q51: 0 | R51: 0 | S51: 0 | T51: 0 | U51: 0 | V51: 0 | W51: =COUNTIFS(Work!$D$3:$D$5800,'CFT Main'!$B52,Work!$N$3:$N$5800,'CFT Main'!$C52,Work!$G$3:$G$5800,"Ongoing",Work!$F$3:$F$5800,W$5) -> 31 | X51: =COUNTIFS(Work!$D$3:$D$5800,'CFT Main'!$B52,Work!$N$3:$N$5800,'CFT Main'!$C52,Work!$G$3:$G$5800,"*Completed",Work!$F$3:$F$5800,W$5) -> 0
A52: 45 | B52: AMARPATAN | C52: LALPUR | D52: MADHI (BIRDUTT) | E52: अश्वनी पटेल | F52: भूपेन्द्र सिंह अति0 | G52: 8 | H52: 0 | I52: 6 | J52: 0 | K52: 0 | L52: 0 | M52: 2 | N52: 0 | O52: 0 | P52: 0 | Q52: 0 | R52: 0 | S52: 0 | T52: 0 | U52: 0 | V52: 0 | W52: =COUNTIFS(Work!$D$3:$D$5800,'CFT Main'!$B53,Work!$N$3:$N$5800,'CFT Main'!$C53,Work!$G$3:$G$5800,"Ongoing",Work!$F$3:$F$5800,W$5) -> 19 | X52: =COUNTIFS(Work!$D$3:$D$5800,'CFT Main'!$B53,Work!$N$3:$N$5800,'CFT Main'!$C53,Work!$G$3:$G$5800,"*Completed",Work!$F$3:$F$5800,W$5) -> 0
A53: 46 | B53: AMARPATAN | C53: PARASWAHI | D53: MAGRAJ | E53: अनिल पटेल अति0 | F53: भूपेन्द्र सिंह अति0 | G53: 8 | H53: 5 | I53: 6 | J53: 1 | K53: 1 | L53: 1 | M53: 0 | N53: 2 | O53: 0 | P53: 0 | Q53: 0 | R53: 1 | S53: 1 | T53: 0 | U53: 0 | V53: 0 | W53: =COUNTIFS(Work!$D$3:$D$5800,'CFT Main'!$B54,Work!$N$3:$N$5800,'CFT Main'!$C54,Work!$G$3:$G$5800,"Ongoing",Work!$F$3:$F$5800,W$5) -> 9 | X53: =COUNTIFS(Work!$D$3:$D$5800,'CFT Main'!$B54,Work!$N$3:$N$5800,'CFT Main'!$C54,Work!$G$3:$G$5800,"*Completed",Work!$F$3:$F$5800,W$5) -> 0
A54: 47 | B54: AMARPATAN | C54: MAUHARI KATARA | D54: MAHUDAR | E54: अनिल पटेल | F54: भूपेन्द्र सिंह अति0 | G54: 8 | H54: 5 | I54: 5 | J54: 4 | K54: 0 | L54: 0 | M54: 3 | N54: 1 | O54: 0 | P54: 0 | Q54: 0 | R54: 0 | S54: 0 | T54: 0 | U54: 0 | V54: 0 | W54: =COUNTIFS(Work!$D$3:$D$5800,'CFT Main'!$B55,Work!$N$3:$N$5800,'CFT Main'!$C55,Work!$G$3:$G$5800,"Ongoing",Work!$F$3:$F$5800,W$5) -> 21 | X54: =COUNTIFS(Work!$D$3:$D$5800,'CFT Main'!$B55,Work!$N$3:$N$5800,'CFT Main'!$C55,Work!$G$3:$G$5800,"*Completed",Work!$F$3:$F$5800,W$5) -> 0
A55: 48 | B55: AMARPATAN | C55: PARASWAHI | D55: MAJHGAWAN | E55: अनिल पटेल अति0 | F55: भूपेन्द्र सिंह अति0 | G55: 8 | H55: 0 | I55: 5 | J55: 0 | K55: 1 | L55: 0 | M55: 1 | N55: 0 | O55: 1 | P55: 0 | Q55: 0 | R55: 0 | S55: 0 | T55: 0 | U55: 0 | V55: 0 | W55: =COUNTIFS(Work!$D$3:$D$5800,'CFT Main'!$B56,Work!$N$3:$N$5800,'CFT Main'!$C56,Work!$G$3:$G$5800,"Ongoing",Work!$F$3:$F$5800,W$5) -> 23 | X55: =COUNTIFS(Work!$D$3:$D$5800,'CFT Main'!$B56,Work!$N$3:$N$5800,'CFT Main'!$C56,Work!$G$3:$G$5800,"*Completed",Work!$F$3:$F$5800,W$5) -> 0
A56: 49 | B56: AMARPATAN | C56: TALA | D56: MARHI (NEAR AJMAIN) | E56: सत्यनारायण मिश्रा | F56: भूपेन्द्र सिंह अति0 | G56: 8 | H56: 0 | I56: 5 | J56: 0 | K56: 0 | L56: 0 | M56: 3 | N56: 0 | O56: 0 | P56: 0 | Q56: 0 | R56: 0 | S56: 0 | T56: 0 | U56: 0 | V56: 0 | W56: =COUNTIFS(Work!$D$3:$D$5800,'CFT Main'!$B57,Work!$N$3:$N$5800,'CFT Main'!$C57,Work!$G$3:$G$5800,"Ongoing",Work!$F$3:$F$5800,W$5) -> 13 | X56: =COUNTIFS(Work!$D$3:$D$5800,'CFT Main'!$B57,Work!$N$3:$N$5800,'CFT Main'!$C57,Work!$G$3:$G$5800,"*Completed",Work!$F$3:$F$5800,W$5) -> 0
... A702: 695 | B702: UNCHAHARA | C702: PONDEE | D702: VICHAVA | E702: हरनाम सिंह | F702: मधु बागरी | G702: 0 | H702: 3 | I702: 0 | J702: 2 | K702: 0 | L702: 1 | M702: 0 | N702: 0 | O702: 0 | P702: 0 | Q702: 0 | R702: 0 | S702: 0 | T702: 0 | U702: 0 | V702: 0 | W702: =COUNTIFS(Work!$D$3:$D$5800,'CFT Main'!$B703,Work!$N$3:$N$5800,'CFT Main'!$C703,Work!$G$3:$G$5800,"Ongoing",Work!$F$3:$F$5800,W$5) -> 0 | X702: =COUNTIFS(Work!$D$3:$D$5800,'CFT Main'!$B703,Work!$N$3:$N$5800,'CFT Main'!$C703,Work!$G$3:$G$5800,"*Completed",Work!$F$3:$F$5800,W$5) -> 0
G829: 2565 | H829: 1259 | I829: 1659 | J829: 729 | K829: 212 | L829: 283 | M829: 460 | N829: 171 | O829: 86 | P829: 25 | Q829: 84 | R829: 34 | S829: 55 | T829: 17 | U829: 9 | V829: 0

Sheet CFT Main
A2: जल गंगा अभियान का नवीन डैशबोर्ड- उपयंत्रीवार नरेगा स्‍कीम - जिला पंचायत सतना 11-05-2026
A5: क्रमांक | B5: जनपद | C5: क्लस्टर | D5: ग्राम पंचायत | E5: उपयंत्री | F5: सहायक यंत्री | G5: 2020-21 | H5: 2021-22 | I5: 2022-23 | J5: 2023-24 | K5: TOTAL | L5: प्रधानमंत्री आवास पोर्टल में आवासों की पूर्णता | M5: 2015-16 | N5: 2016-17 | O5: 2017-18 | P5: 2018-19 | Q5: 2019-20 | R5: 2020-21 | S5: 2021-22 | T5: 2022-23 | U5: 2023-24 | V5: मनरेगा पोर्टल में आवासों की पूर्णता | W5: मनरेगा पोर्टल पर आवास की पूर्णता दर्ज किया जाना शेष | X5: R14.4 Status of Timely Payment | Y5: Total No. of Aadhaar seeded in MIS | Z5: Blance Aadhaar seeded in MIS | AA5: Total No. of works having >=20 workers | AB5: Out of Col(1), No. of works having musterroll filled through NMMS App. | AC5: Progress % | AD5: Total No. of works having >=20 workers | AE5: Out of Col(1), No. of works having musterroll filled through NMMS App. | AF5: Progress % | AG5: GPs With device registration but NMMS yet Not started | AH5: Eligible Worksites but NMMS Yet not started | AI5: प्रगतिरत सामुदायिक कार्यो की संख्या | AJ5: आधार आधारित भुगतान नही होने वाले श्रमिको की संख्या | AK5: 03-05-2023 Authentication Failed | AL5: Progress | AM5: सहायक यंत्री | AN5: Total Ongoing | AO5: Total Completed | AP5: Farm Pond | AR5: Dug Well Recharge | AT5: Water conservation & recharge | AV5: Repair & Maintenance (Water Structures) | AX5: Watershed Related Works | AZ5: Irrigation infrastructure | BB5: Amrit Sarowar | BD5: Gap Filling in Plantation
D6: 4 | F6: 6 | G6: 32 | H6: 33 | I6: 34 | J6: 35 | K6: 36 | L6: 37 | M6: 38 | N6: 39 | O6: 40 | P6: 41 | Q6: 42 | R6: 43 | S6: 44 | T6: 45 | U6: 46 | V6: 47 | W6: 48 | X6: 49 | Y6: 50 | Z6: 51 | AA6: 52 | AB6: 53 | AC6: 54 | AD6: 55 | AE6: 56 | AF6: 57 | AG6: 58 | AH6: 59 | AI6: 60 | AJ6: 61 | AK6: 62 | AL6: 63 | AP6: Ongoing | AQ6: Completed | AR6: Ongoing | AS6: Completed | AT6: Ongoing | AU6: Completed | AV6: Ongoing | AW6: Completed | AX6: Ongoing | AY6: Completed | AZ6: Ongoing | BA6: Completed | BB6: Ongoing | BC6: Completed | BD6: Ongoing | BE6: Completed
A7: 1 | B7: AMARPATAN | C7: RAMGARH | D7: AKAURI | E7: श्रीमती साधना चौरे | F7: Add. NIKHIL MISHRA | G7: =SUMIFS(#REF!,'GP Main'!$B$8:$B$827,'CFT Main'!$B9,'GP Main'!$C$8:$C$827,'CFT Main'!$C9) -> #REF! | H7: =SUMIFS(#REF!,'GP Main'!$B$8:$B$827,'CFT Main'!$B9,'GP Main'!$C$8:$C$827,'CFT Main'!$C9) -> #REF! | I7: =SUMIFS(#REF!,'GP Main'!$B$8:$B$827,'CFT Main'!$B9,'GP Main'!$C$8:$C$827,'CFT Main'!$C9) -> #REF! | J7: =SUMIFS(#REF!,'GP Main'!$B$8:$B$827,'CFT Main'!$B9,'GP Main'!$C$8:$C$827,'CFT Main'!$C9) -> #REF! | K7: =SUMIFS(#REF!,'GP Main'!$B$8:$B$827,'CFT Main'!$B9,'GP Main'!$C$8:$C$827,'CFT Main'!$C9) -> #REF! | L7: =SUMIFS(#REF!,'GP Main'!$B$8:$B$827,'CFT Main'!$B9,'GP Main'!$C$8:$C$827,'CFT Main'!$C9) -> #REF! | M7: =SUMIFS(#REF!,'GP Main'!$B$8:$B$827,'CFT Main'!$B9,'GP Main'!$C$8:$C$827,'CFT Main'!$C9) -> #REF! | N7: =SUMIFS(#REF!,'GP Main'!$B$8:$B$827,'CFT Main'!$B9,'GP Main'!$C$8:$C$827,'CFT Main'!$C9) -> #REF! | ... AB7: =SUMIFS(#REF!,'GP Main'!$B$8:$B$827,'CFT Main'!$B9,'GP Main'!$C$8:$C$827,'CFT Main'!$C9) -> #REF! | AD7: =SUMIFS(#REF!,'GP Main'!$B$8:$B$827,'CFT Main'!$B9,'GP Main'!$C$8:$C$827,'CFT Main'!$C9) -> #REF! | AE7: =SUMIFS(#REF!,'GP Main'!$B$8:$B$827,'CFT Main'!$B9,'GP Main'!$C$8:$C$827,'CFT Main'!$C9) -> #REF! | AG7: =SUMIFS(#REF!,'GP Main'!$B$8:$B$827,'CFT Main'!$B9,'GP Main'!$C$8:$C$827,'CFT Main'!$C9) -> #REF! | AH7: =SUMIFS(#REF!,'GP Main'!$B$8:$B$827,'CFT Main'!$B9,'GP Main'!$C$8:$C$827,'CFT Main'!$C9) -> #REF! | AI7: =SUMIFS(#REF!,'GP Main'!$B$8:$B$827,'CFT Main'!$B9,'GP Main'!$C$8:$C$827,'CFT Main'!$C9) -> #REF! | AJ7: =SUMIFS(#REF!,'GP Main'!$B$8:$B$827,'CFT Main'!$B9,'GP Main'!$C$8:$C$827,'CFT Main'!$C9) -> #REF! | AK7: =SUMIFS(#REF!,'GP Main'!$B$8:$B$695,'CFT Main'!$B9,'GP Main'!$C$8:$C$695,'CFT Main'!$C9) -> #REF! | AM7: भूपेन्द्र सिंह अति0 | AN7: =COUNTIFS(Work!$D$3:$D$5800,'CFT Main'!$B7,Work!$N$3:$N$5800,'CFT Main'!$C7,Work!$G$3:$G$5800,"Ongoing") -> 45 | AO7: =COUNTIFS(Work!$D$3:$D$5800,'CFT Main'!$B7,Work!$N$3:$N$5800,'CFT Main'!$C7,Work!$G$3:$G$5800,"*Completed") -> 25 | AP7: =COUNTIFS(Work!$D$3:$D$5800,'CFT Main'!$B7,Work!$N$3:$N$5800,'CFT Main'!$C7,Work!$G$3:$G$5800,"Ongoing",Work!$F$3:$F$5800,AP$5) -> 8 | AQ7: =COUNTIFS(Work!$D$3:$D$5800,'CFT Main'!$B7,Work!$N$3:$N$5800,'CFT Main'!$C7,Work!$G$3:$G$5800,"*Completed",Work!$F$3:$F$5800,AP$5) -> 5 | AR7: =COUNTIFS(Work!$D$3:$D$5800,'CFT Main'!$B7,Work!$N$3:$N$5800,'CFT Main'!$C7,Work!$G$3:$G$5800,"Ongoing",Work!$F$3:$F$5800,AR$5) -> 1 | AS7: =COUNTIFS(Work!$D$3:$D$5800,'CFT Main'!$B7,Work!$N$3:$N$5800,'CFT Main'!$C7,Work!$G$3:$G$5800,"*Completed",Work!$F$3:$F$5800,AR$5) -> 18 | AT7: =COUNTIFS(Work!$D$3:$D$5800,'CFT Main'!$B7,Work!$N$3:$N$5800,'CFT Main'!$C7,Work!$G$3:$G$5800,"Ongoing",Work!$F$3:$F$5800,AT$5) -> 0 | AU7: =COUNTIFS(Work!$D$3:$D$5800,'CFT Main'!$B7,Work!$N$3:$N$5800,'CFT Main'!$C7,Work!$G$3:$G$5800,"*Completed",Work!$F$3:$F$5800,AT$5) -> 1 | AV7: =COUNTIFS(Work!$D$3:$D$5800,'CFT Main'!$B7,Work!$N$3:$N$5800,'CFT Main'!$C7,Work!$G$3:$G$5800,"Ongoing",Work!$F$3:$F$5800,AV$5) -> 0 | AW7: =COUNTIFS(Work!$D$3:$D$5800,'CFT Main'!$B7,Work!$N$3:$N$5800,'CFT Main'!$C7,Work!$G$3:$G$5800,"*Completed",Work!$F$3:$F$5800,AV$5) -> 1 | AX7: =COUNTIFS(Work!$D$3:$D$5800,'CFT Main'!$B7,Work!$N$3:$N$5800,'CFT Main'!$C7,Work!$G$3:$G$5800,"Ongoing",Work!$F$3:$F$5800,AX$5) -> 0 | AY7: =COUNTIFS(Work!$D$3:$D$5800,'CFT Main'!$B7,Work!$N$3:$N$5800,'CFT Main'!$C7,Work!$G$3:$G$5800,"*Completed",Work!$F$3:$F$5800,AX$5) -> 0 | AZ7: =COUNTIFS(Work!$D$3:$D$5800,'CFT Main'!$B7,Work!$N$3:$N$5800,'CFT Main'!$C7,Work!$G$3:$G$5800,"Ongoing",Work!$F$3:$F$5800,AZ$5) -> 0 | BA7: =COUNTIFS(Work!$D$3:$D$5800,'CFT Main'!$B7,Work!$N$3:$N$5800,'CFT Main'!$C7,Work!$G$3:$G$5800,"*Completed",Work!$F$3:$F$5800,AZ$5) -> 0 | BB7: =COUNTIFS(Work!$D$3:$D$5800,'CFT Main'!$B7,Work!$N$3:$N$5800,'CFT Main'!$C7,Work!$G$3:$G$5800,"Ongoing",Work!$F$3:$F$5800,BB$5) -> 0 | BC7: =COUNTIFS(Work!$D$3:$D$5800,'CFT Main'!$B7,Work!$N$3:$N$5800,'CFT Main'!$C7,Work!$G$3:$G$5800,"*Completed",Work!$F$3:$F$5800,BB$5) -> 0 | BD7: =COUNTIFS(Work!$D$3:$D$5800,'CFT Main'!$B7,Work!$N$3:$N$5800,'CFT Main'!$C7,Work!$G$3:$G$5800,"Ongoing",Work!$F$3:$F$5800,BD$5) -> 36 | BE7: =COUNTIFS(Work!$D$3:$D$5800,'CFT Main'!$B7,Work!$N$3:$N$5800,'CFT Main'!$C7,Work!$G$3:$G$5800,"*Completed",Work!$F$3:$F$5800,BD$5) -> 0
A8: 2 | B8: AMARPATAN | C8: TALA | D8: AGADAL | E8: सत्यनारायण मिश्रा | F8: Add. NIKHIL MISHRA | G8: =SUMIFS(#REF!,'GP Main'!$B$8:$B$827,'CFT Main'!$B8,'GP Main'!$C$8:$C$827,'CFT Main'!$C8) -> #REF! | H8: =SUMIFS(#REF!,'GP Main'!$B$8:$B$827,'CFT Main'!$B8,'GP Main'!$C$8:$C$827,'CFT Main'!$C8) -> #REF! | I8: =SUMIFS(#REF!,'GP Main'!$B$8:$B$827,'CFT Main'!$B8,'GP Main'!$C$8:$C$827,'CFT Main'!$C8) -> #REF! | J8: =SUMIFS(#REF!,'GP Main'!$B$8:$B$827,'CFT Main'!$B8,'GP Main'!$C$8:$C$827,'CFT Main'!$C8) -> #REF! | K8: =SUMIFS(#REF!,'GP Main'!$B$8:$B$827,'CFT Main'!$B8,'GP Main'!$C$8:$C$827,'CFT Main'!$C8) -> #REF! | L8: =SUMIFS(#REF!,'GP Main'!$B$8:$B$827,'CFT Main'!$B8,'GP Main'!$C$8:$C$827,'CFT Main'!$C8) -> #REF! | M8: =SUMIFS(#REF!,'GP Main'!$B$8:$B$827,'CFT Main'!$B8,'GP Main'!$C$8:$C$827,'CFT Main'!$C8) -> #REF! | N8: =SUMIFS(#REF!,'GP Main'!$B$8:$B$827,'CFT Main'!$B8,'GP Main'!$C$8:$C$827,'CFT Main'!$C8) -> #REF! | ... AB8: =SUMIFS(#REF!,'GP Main'!$B$8:$B$827,'CFT Main'!$B8,'GP Main'!$C$8:$C$827,'CFT Main'!$C8) -> #REF! | AD8: =SUMIFS(#REF!,'GP Main'!$B$8:$B$827,'CFT Main'!$B8,'GP Main'!$C$8:$C$827,'CFT Main'!$C8) -> #REF! | AE8: =SUMIFS(#REF!,'GP Main'!$B$8:$B$827,'CFT Main'!$B8,'GP Main'!$C$8:$C$827,'CFT Main'!$C8) -> #REF! | AG8: =SUMIFS(#REF!,'GP Main'!$B$8:$B$827,'CFT Main'!$B8,'GP Main'!$C$8:$C$827,'CFT Main'!$C8) -> #REF! | AH8: =SUMIFS(#REF!,'GP Main'!$B$8:$B$827,'CFT Main'!$B8,'GP Main'!$C$8:$C$827,'CFT Main'!$C8) -> #REF! | AI8: =SUMIFS(#REF!,'GP Main'!$B$8:$B$827,'CFT Main'!$B8,'GP Main'!$C$8:$C$827,'CFT Main'!$C8) -> #REF! | AJ8: =SUMIFS(#REF!,'GP Main'!$B$8:$B$827,'CFT Main'!$B8,'GP Main'!$C$8:$C$827,'CFT Main'!$C8) -> #REF! | AK8: =SUMIFS(#REF!,'GP Main'!$B$8:$B$827,'CFT Main'!$B8,'GP Main'!$C$8:$C$827,'CFT Main'!$C8) -> #REF! | AM8: भूपेन्द्र सिंह अति0 | AN8: =COUNTIFS(Work!$D$3:$D$5800,'CFT Main'!$B8,Work!$N$3:$N$5800,'CFT Main'!$C8,Work!$G$3:$G$5800,"Ongoing") -> 44 | AO8: =COUNTIFS(Work!$D$3:$D$5800,'CFT Main'!$B8,Work!$N$3:$N$5800,'CFT Main'!$C8,Work!$G$3:$G$5800,"*Completed") -> 25 | AP8: =COUNTIFS(Work!$D$3:$D$5800,'CFT Main'!$B8,Work!$N$3:$N$5800,'CFT Main'!$C8,Work!$G$3:$G$5800,"Ongoing",Work!$F$3:$F$5800,AP$5) -> 9 | AQ8: =COUNTIFS(Work!$D$3:$D$5800,'CFT Main'!$B8,Work!$N$3:$N$5800,'CFT Main'!$C8,Work!$G$3:$G$5800,"*Completed",Work!$F$3:$F$5800,AP$5) -> 3 | AR8: =COUNTIFS(Work!$D$3:$D$5800,'CFT Main'!$B8,Work!$N$3:$N$5800,'CFT Main'!$C8,Work!$G$3:$G$5800,"Ongoing",Work!$F$3:$F$5800,AR$5) -> 0 | AS8: =COUNTIFS(Work!$D$3:$D$5800,'CFT Main'!$B8,Work!$N$3:$N$5800,'CFT Main'!$C8,Work!$G$3:$G$5800,"*Completed",Work!$F$3:$F$5800,AR$5) -> 16 | AT8: =COUNTIFS(Work!$D$3:$D$5800,'CFT Main'!$B8,Work!$N$3:$N$5800,'CFT Main'!$C8,Work!$G$3:$G$5800,"Ongoing",Work!$F$3:$F$5800,AT$5) -> 0 | AU8: =COUNTIFS(Work!$D$3:$D$5800,'CFT Main'!$B8,Work!$N$3:$N$5800,'CFT Main'!$C8,Work!$G$3:$G$5800,"*Completed",Work!$F$3:$F$5800,AT$5) -> 6 | AV8: =COUNTIFS(Work!$D$3:$D$5800,'CFT Main'!$B8,Work!$N$3:$N$5800,'CFT Main'!$C8,Work!$G$3:$G$5800,"Ongoing",Work!$F$3:$F$5800,AV$5) -> 0 | AW8: =COUNTIFS(Work!$D$3:$D$5800,'CFT Main'!$B8,Work!$N$3:$N$5800,'CFT Main'!$C8,Work!$G$3:$G$5800,"*Completed",Work!$F$3:$F$5800,AV$5) -> 0 | AX8: =COUNTIFS(Work!$D$3:$D$5800,'CFT Main'!$B8,Work!$N$3:$N$5800,'CFT Main'!$C8,Work!$G$3:$G$5800,"Ongoing",Work!$F$3:$F$5800,AX$5) -> 0 | AY8: =COUNTIFS(Work!$D$3:$D$5800,'CFT Main'!$B8,Work!$N$3:$N$5800,'CFT Main'!$C8,Work!$G$3:$G$5800,"*Completed",Work!$F$3:$F$5800,AX$5) -> 0 | AZ8: =COUNTIFS(Work!$D$3:$D$5800,'CFT Main'!$B8,Work!$N$3:$N$5800,'CFT Main'!$C8,Work!$G$3:$G$5800,"Ongoing",Work!$F$3:$F$5800,AZ$5) -> 0 | BA8: =COUNTIFS(Work!$D$3:$D$5800,'CFT Main'!$B8,Work!$N$3:$N$5800,'CFT Main'!$C8,Work!$G$3:$G$5800,"*Completed",Work!$F$3:$F$5800,AZ$5) -> 0 | BB8: =COUNTIFS(Work!$D$3:$D$5800,'CFT Main'!$B8,Work!$N$3:$N$5800,'CFT Main'!$C8,Work!$G$3:$G$5800,"Ongoing",Work!$F$3:$F$5800,BB$5) -> 0 | BC8: =COUNTIFS(Work!$D$3:$D$5800,'CFT Main'!$B8,Work!$N$3:$N$5800,'CFT Main'!$C8,Work!$G$3:$G$5800,"*Completed",Work!$F$3:$F$5800,BB$5) -> 0 | BD8: =COUNTIFS(Work!$D$3:$D$5800,'CFT Main'!$B8,Work!$N$3:$N$5800,'CFT Main'!$C8,Work!$G$3:$G$5800,"Ongoing",Work!$F$3:$F$5800,BD$5) -> 35 | BE8: =COUNTIFS(Work!$D$3:$D$5800,'CFT Main'!$B8,Work!$N$3:$N$5800,'CFT Main'!$C8,Work!$G$3:$G$5800,"*Completed",Work!$F$3:$F$5800,BD$5) -> 0
A9: 3 | B9: AMARPATAN | C9: LALPUR | D9: CHHIULA | E9: अश्वनी पटेल | F9: Add. NIKHIL MISHRA | G9: =SUMIFS(#REF!,'GP Main'!$B$8:$B$827,'CFT Main'!$B13,'GP Main'!$C$8:$C$827,'CFT Main'!$C13) -> #REF! | H9: =SUMIFS(#REF!,'GP Main'!$B$8:$B$827,'CFT Main'!$B13,'GP Main'!$C$8:$C$827,'CFT Main'!$C13) -> #REF! | I9: =SUMIFS(#REF!,'GP Main'!$B$8:$B$827,'CFT Main'!$B13,'GP Main'!$C$8:$C$827,'CFT Main'!$C13) -> #REF! | J9: =SUMIFS(#REF!,'GP Main'!$B$8:$B$827,'CFT Main'!$B13,'GP Main'!$C$8:$C$827,'CFT Main'!$C13) -> #REF! | K9: =SUMIFS(#REF!,'GP Main'!$B$8:$B$827,'CFT Main'!$B13,'GP Main'!$C$8:$C$827,'CFT Main'!$C13) -> #REF! | L9: =SUMIFS(#REF!,'GP Main'!$B$8:$B$827,'CFT Main'!$B13,'GP Main'!$C$8:$C$827,'CFT Main'!$C13) -> #REF! | M9: =SUMIFS(#REF!,'GP Main'!$B$8:$B$827,'CFT Main'!$B13,'GP Main'!$C$8:$C$827,'CFT Main'!$C13) -> #REF! | N9: =SUMIFS(#REF!,'GP Main'!$B$8:$B$827,'CFT Main'!$B13,'GP Main'!$C$8:$C$827,'CFT Main'!$C13) -> #REF! | ... AB9: =SUMIFS(#REF!,'GP Main'!$B$8:$B$827,'CFT Main'!$B13,'GP Main'!$C$8:$C$827,'CFT Main'!$C13) -> #REF! | AD9: =SUMIFS(#REF!,'GP Main'!$B$8:$B$827,'CFT Main'!$B13,'GP Main'!$C$8:$C$827,'CFT Main'!$C13) -> #REF! | AE9: =SUMIFS(#REF!,'GP Main'!$B$8:$B$827,'CFT Main'!$B13,'GP Main'!$C$8:$C$827,'CFT Main'!$C13) -> #REF! | AG9: =SUMIFS(#REF!,'GP Main'!$B$8:$B$827,'CFT Main'!$B13,'GP Main'!$C$8:$C$827,'CFT Main'!$C13) -> #REF! | AH9: =SUMIFS(#REF!,'GP Main'!$B$8:$B$827,'CFT Main'!$B13,'GP Main'!$C$8:$C$827,'CFT Main'!$C13) -> #REF! | AI9: =SUMIFS(#REF!,'GP Main'!$B$8:$B$827,'CFT Main'!$B13,'GP Main'!$C$8:$C$827,'CFT Main'!$C13) -> #REF! | AJ9: =SUMIFS(#REF!,'GP Main'!$B$8:$B$827,'CFT Main'!$B13,'GP Main'!$C$8:$C$827,'CFT Main'!$C13) -> #REF! | AK9: =SUMIFS(#REF!,'GP Main'!$B$8:$B$827,'CFT Main'!$B13,'GP Main'!$C$8:$C$827,'CFT Main'!$C13) -> #REF! | AM9: भूपेन्द्र सिंह अति0 | AN9: =COUNTIFS(Work!$D$3:$D$5800,'CFT Main'!$B9,Work!$N$3:$N$5800,'CFT Main'!$C9,Work!$G$3:$G$5800,"Ongoing") -> 51 | AO9: =COUNTIFS(Work!$D$3:$D$5800,'CFT Main'!$B9,Work!$N$3:$N$5800,'CFT Main'!$C9,Work!$G$3:$G$5800,"*Completed") -> 33 | AP9: =COUNTIFS(Work!$D$3:$D$5800,'CFT Main'!$B9,Work!$N$3:$N$5800,'CFT Main'!$C9,Work!$G$3:$G$5800,"Ongoing",Work!$F$3:$F$5800,AP$5) -> 8 | AQ9: =COUNTIFS(Work!$D$3:$D$5800,'CFT Main'!$B9,Work!$N$3:$N$5800,'CFT Main'!$C9,Work!$G$3:$G$5800,"*Completed",Work!$F$3:$F$5800,AP$5) -> 7 | AR9: =COUNTIFS(Work!$D$3:$D$5800,'CFT Main'!$B9,Work!$N$3:$N$5800,'CFT Main'!$C9,Work!$G$3:$G$5800,"Ongoing",Work!$F$3:$F$5800,AR$5) -> 3 | AS9: =COUNTIFS(Work!$D$3:$D$5800,'CFT Main'!$B9,Work!$N$3:$N$5800,'CFT Main'!$C9,Work!$G$3:$G$5800,"*Completed",Work!$F$3:$F$5800,AR$5) -> 18 | AT9: =COUNTIFS(Work!$D$3:$D$5800,'CFT Main'!$B9,Work!$N$3:$N$5800,'CFT Main'!$C9,Work!$G$3:$G$5800,"Ongoing",Work!$F$3:$F$5800,AT$5) -> 0 | AU9: =COUNTIFS(Work!$D$3:$D$5800,'CFT Main'!$B9,Work!$N$3:$N$5800,'CFT Main'!$C9,Work!$G$3:$G$5800,"*Completed",Work!$F$3:$F$5800,AT$5) -> 7 | AV9: =COUNTIFS(Work!$D$3:$D$5800,'CFT Main'!$B9,Work!$N$3:$N$5800,'CFT Main'!$C9,Work!$G$3:$G$5800,"Ongoing",Work!$F$3:$F$5800,AV$5) -> 0 | AW9: =COUNTIFS(Work!$D$3:$D$5800,'CFT Main'!$B9,Work!$N$3:$N$5800,'CFT Main'!$C9,Work!$G$3:$G$5800,"*Completed",Work!$F$3:$F$5800,AV$5) -> 1 | AX9: =COUNTIFS(Work!$D$3:$D$5800,'CFT Main'!$B9,Work!$N$3:$N$5800,'CFT Main'!$C9,Work!$G$3:$G$5800,"Ongoing",Work!$F$3:$F$5800,AX$5) -> 0 | AY9: =COUNTIFS(Work!$D$3:$D$5800,'CFT Main'!$B9,Work!$N$3:$N$5800,'CFT Main'!$C9,Work!$G$3:$G$5800,"*Completed",Work!$F$3:$F$5800,AX$5) -> 0 | AZ9: =COUNTIFS(Work!$D$3:$D$5800,'CFT Main'!$B9,Work!$N$3:$N$5800,'CFT Main'!$C9,Work!$G$3:$G$5800,"Ongoing",Work!$F$3:$F$5800,AZ$5) -> 0 | BA9: =COUNTIFS(Work!$D$3:$D$5800,'CFT Main'!$B9,Work!$N$3:$N$5800,'CFT Main'!$C9,Work!$G$3:$G$5800,"*Completed",Work!$F$3:$F$5800,AZ$5) -> 0 | BB9: =COUNTIFS(Work!$D$3:$D$5800,'CFT Main'!$B9,Work!$N$3:$N$5800,'CFT Main'!$C9,Work!$G$3:$G$5800,"Ongoing",Work!$F$3:$F$5800,BB$5) -> 0 | BC9: =COUNTIFS(Work!$D$3:$D$5800,'CFT Main'!$B9,Work!$N$3:$N$5800,'CFT Main'!$C9,Work!$G$3:$G$5800,"*Completed",Work!$F$3:$F$5800,BB$5) -> 0 | BD9: =COUNTIFS(Work!$D$3:$D$5800,'CFT Main'!$B9,Work!$N$3:$N$5800,'CFT Main'!$C9,Work!$G$3:$G$5800,"Ongoing",Work!$F$3:$F$5800,BD$5) -> 40 | BE9: =COUNTIFS(Work!$D$3:$D$5800,'CFT Main'!$B9,Work!$N$3:$N$5800,'CFT Main'!$C9,Work!$G$3:$G$5800,"*Completed",Work!$F$3:$F$5800,BD$5) -> 0
A10: 4 | B10: AMARPATAN | C10: BELA | D10: BHAUKHARI KHURD | E10: सुनील मिश्रा | F10: Add. NIKHIL MISHRA | G10: =SUMIFS(#REF!,'GP Main'!$B$8:$B$827,'CFT Main'!$B12,'GP Main'!$C$8:$C$827,'CFT Main'!$C12) -> #REF! | H10: =SUMIFS(#REF!,'GP Main'!$B$8:$B$827,'CFT Main'!$B12,'GP Main'!$C$8:$C$827,'CFT Main'!$C12) -> #REF! | I10: =SUMIFS(#REF!,'GP Main'!$B$8:$B$827,'CFT Main'!$B12,'GP Main'!$C$8:$C$827,'CFT Main'!$C12) -> #REF! | J10: =SUMIFS(#REF!,'GP Main'!$B$8:$B$827,'CFT Main'!$B12,'GP Main'!$C$8:$C$827,'CFT Main'!$C12) -> #REF! | K10: =SUMIFS(#REF!,'GP Main'!$B$8:$B$827,'CFT Main'!$B12,'GP Main'!$C$8:$C$827,'CFT Main'!$C12) -> #REF! | L10: =SUMIFS(#REF!,'GP Main'!$B$8:$B$827,'CFT Main'!$B12,'GP Main'!$C$8:$C$827,'CFT Main'!$C12) -> #REF! | M10: =SUMIFS(#REF!,'GP Main'!$B$8:$B$827,'CFT Main'!$B12,'GP Main'!$C$8:$C$827,'CFT Main'!$C12) -> #REF! | N10: =SUMIFS(#REF!,'GP Main'!$B$8:$B$827,'CFT Main'!$B12,'GP Main'!$C$8:$C$827,'CFT Main'!$C12) -> #REF! | ... AB10: =SUMIFS(#REF!,'GP Main'!$B$8:$B$827,'CFT Main'!$B12,'GP Main'!$C$8:$C$827,'CFT Main'!$C12) -> #REF! | AD10: =SUMIFS(#REF!,'GP Main'!$B$8:$B$827,'CFT Main'!$B12,'GP Main'!$C$8:$C$827,'CFT Main'!$C12) -> #REF! | AE10: =SUMIFS(#REF!,'GP Main'!$B$8:$B$827,'CFT Main'!$B12,'GP Main'!$C$8:$C$827,'CFT Main'!$C12) -> #REF! | AG10: =SUMIFS(#REF!,'GP Main'!$B$8:$B$827,'CFT Main'!$B12,'GP Main'!$C$8:$C$827,'CFT Main'!$C12) -> #REF! | AH10: =SUMIFS(#REF!,'GP Main'!$B$8:$B$827,'CFT Main'!$B12,'GP Main'!$C$8:$C$827,'CFT Main'!$C12) -> #REF! | AI10: =SUMIFS(#REF!,'GP Main'!$B$8:$B$827,'CFT Main'!$B12,'GP Main'!$C$8:$C$827,'CFT Main'!$C12) -> #REF! | AJ10: =SUMIFS(#REF!,'GP Main'!$B$8:$B$827,'CFT Main'!$B12,'GP Main'!$C$8:$C$827,'CFT Main'!$C12) -> #REF! | AK10: =SUMIFS(#REF!,'GP Main'!$B$8:$B$827,'CFT Main'!$B12,'GP Main'!$C$8:$C$827,'CFT Main'!$C12) -> #REF! | AM10: भूपेन्द्र सिंह अति0 | AN10: =COUNTIFS(Work!$D$3:$D$5800,'CFT Main'!$B10,Work!$N$3:$N$5800,'CFT Main'!$C10,Work!$G$3:$G$5800,"Ongoing") -> 35 | AO10: =COUNTIFS(Work!$D$3:$D$5800,'CFT Main'!$B10,Work!$N$3:$N$5800,'CFT Main'!$C10,Work!$G$3:$G$5800,"*Completed") -> 14 | AP10: =COUNTIFS(Work!$D$3:$D$5800,'CFT Main'!$B10,Work!$N$3:$N$5800,'CFT Main'!$C10,Work!$G$3:$G$5800,"Ongoing",Work!$F$3:$F$5800,AP$5) -> 7 | AQ10: =COUNTIFS(Work!$D$3:$D$5800,'CFT Main'!$B10,Work!$N$3:$N$5800,'CFT Main'!$C10,Work!$G$3:$G$5800,"*Completed",Work!$F$3:$F$5800,AP$5) -> 3 | AR10: =COUNTIFS(Work!$D$3:$D$5800,'CFT Main'!$B10,Work!$N$3:$N$5800,'CFT Main'!$C10,Work!$G$3:$G$5800,"Ongoing",Work!$F$3:$F$5800,AR$5) -> 3 | AS10: =COUNTIFS(Work!$D$3:$D$5800,'CFT Main'!$B10,Work!$N$3:$N$5800,'CFT Main'!$C10,Work!$G$3:$G$5800,"*Completed",Work!$F$3:$F$5800,AR$5) -> 6 | AT10: =COUNTIFS(Work!$D$3:$D$5800,'CFT Main'!$B10,Work!$N$3:$N$5800,'CFT Main'!$C10,Work!$G$3:$G$5800,"Ongoing",Work!$F$3:$F$5800,AT$5) -> 0 | AU10: =COUNTIFS(Work!$D$3:$D$5800,'CFT Main'!$B10,Work!$N$3:$N$5800,'CFT Main'!$C10,Work!$G$3:$G$5800,"*Completed",Work!$F$3:$F$5800,AT$5) -> 3 | AV10: =COUNTIFS(Work!$D$3:$D$5800,'CFT Main'!$B10,Work!$N$3:$N$5800,'CFT Main'!$C10,Work!$G$3:$G$5800,"Ongoing",Work!$F$3:$F$5800,AV$5) -> 0 | AW10: =COUNTIFS(Work!$D$3:$D$5800,'CFT Main'!$B10,Work!$N$3:$N$5800,'CFT Main'!$C10,Work!$G$3:$G$5800,"*Completed",Work!$F$3:$F$5800,AV$5) -> 2 | AX10: =COUNTIFS(Work!$D$3:$D$5800,'CFT Main'!$B10,Work!$N$3:$N$5800,'CFT Main'!$C10,Work!$G$3:$G$5800,"Ongoing",Work!$F$3:$F$5800,AX$5) -> 0 | AY10: =COUNTIFS(Work!$D$3:$D$5800,'CFT Main'!$B10,Work!$N$3:$N$5800,'CFT Main'!$C10,Work!$G$3:$G$5800,"*Completed",Work!$F$3:$F$5800,AX$5) -> 0 | AZ10: =COUNTIFS(Work!$D$3:$D$5800,'CFT Main'!$B10,Work!$N$3:$N$5800,'CFT Main'!$C10,Work!$G$3:$G$5800,"Ongoing",Work!$F$3:$F$5800,AZ$5) -> 0 | BA10: =COUNTIFS(Work!$D$3:$D$5800,'CFT Main'!$B10,Work!$N$3:$N$5800,'CFT Main'!$C10,Work!$G$3:$G$5800,"*Completed",Work!$F$3:$F$5800,AZ$5) -> 0 | BB10: =COUNTIFS(Work!$D$3:$D$5800,'CFT Main'!$B10,Work!$N$3:$N$5800,'CFT Main'!$C10,Work!$G$3:$G$5800,"Ongoing",Work!$F$3:$F$5800,BB$5) -> 0 | BC10: =COUNTIFS(Work!$D$3:$D$5800,'CFT Main'!$B10,Work!$N$3:$N$5800,'CFT Main'!$C10,Work!$G$3:$G$5800,"*Completed",Work!$F$3:$F$5800,BB$5) -> 0 | BD10: =COUNTIFS(Work!$D$3:$D$5800,'CFT Main'!$B10,Work!$N$3:$N$5800,'CFT Main'!$C10,Work!$G$3:$G$5800,"Ongoing",Work!$F$3:$F$5800,BD$5) -> 25 | BE10: =COUNTIFS(Work!$D$3:$D$5800,'CFT Main'!$B10,Work!$N$3:$N$5800,'CFT Main'!$C10,Work!$G$3:$G$5800,"*Completed",Work!$F$3:$F$5800,BD$5) -> 0
A11: 5 | B11: AMARPATAN | C11: MAUHARI KATARA | D11: BASEDA | E11: अनिल पटेल | F11: Add. NIKHIL MISHRA | G11: =SUMIFS(#REF!,'GP Main'!$B$8:$B$827,'CFT Main'!$B11,'GP Main'!$C$8:$C$827,'CFT Main'!$C11) -> #REF! | H11: =SUMIFS(#REF!,'GP Main'!$B$8:$B$827,'CFT Main'!$B11,'GP Main'!$C$8:$C$827,'CFT Main'!$C11) -> #REF! | I11: =SUMIFS(#REF!,'GP Main'!$B$8:$B$827,'CFT Main'!$B11,'GP Main'!$C$8:$C$827,'CFT Main'!$C11) -> #REF! | J11: =SUMIFS(#REF!,'GP Main'!$B$8:$B$827,'CFT Main'!$B11,'GP Main'!$C$8:$C$827,'CFT Main'!$C11) -> #REF! | K11: =SUMIFS(#REF!,'GP Main'!$B$8:$B$827,'CFT Main'!$B11,'GP Main'!$C$8:$C$827,'CFT Main'!$C11) -> #REF! | L11: =SUMIFS(#REF!,'GP Main'!$B$8:$B$827,'CFT Main'!$B11,'GP Main'!$C$8:$C$827,'CFT Main'!$C11) -> #REF! | M11: =SUMIFS(#REF!,'GP Main'!$B$8:$B$827,'CFT Main'!$B11,'GP Main'!$C$8:$C$827,'CFT Main'!$C11) -> #REF! | N11: =SUMIFS(#REF!,'GP Main'!$B$8:$B$827,'CFT Main'!$B11,'GP Main'!$C$8:$C$827,'CFT Main'!$C11) -> #REF! | ... AB11: =SUMIFS(#REF!,'GP Main'!$B$8:$B$827,'CFT Main'!$B11,'GP Main'!$C$8:$C$827,'CFT Main'!$C11) -> #REF! | AD11: =SUMIFS(#REF!,'GP Main'!$B$8:$B$827,'CFT Main'!$B11,'GP Main'!$C$8:$C$827,'CFT Main'!$C11) -> #REF! | AE11: =SUMIFS(#REF!,'GP Main'!$B$8:$B$827,'CFT Main'!$B11,'GP Main'!$C$8:$C$827,'CFT Main'!$C11) -> #REF! | AG11: =SUMIFS(#REF!,'GP Main'!$B$8:$B$827,'CFT Main'!$B11,'GP Main'!$C$8:$C$827,'CFT Main'!$C11) -> #REF! | AH11: =SUMIFS(#REF!,'GP Main'!$B$8:$B$827,'CFT Main'!$B11,'GP Main'!$C$8:$C$827,'CFT Main'!$C11) -> #REF! | AI11: =SUMIFS(#REF!,'GP Main'!$B$8:$B$827,'CFT Main'!$B11,'GP Main'!$C$8:$C$827,'CFT Main'!$C11) -> #REF! | AJ11: =SUMIFS(#REF!,'GP Main'!$B$8:$B$827,'CFT Main'!$B11,'GP Main'!$C$8:$C$827,'CFT Main'!$C11) -> #REF! | AK11: =SUMIFS(#REF!,'GP Main'!$B$8:$B$827,'CFT Main'!$B11,'GP Main'!$C$8:$C$827,'CFT Main'!$C11) -> #REF! | AM11: भूपेन्द्र सिंह अति0 | AN11: =COUNTIFS(Work!$D$3:$D$5800,'CFT Main'!$B11,Work!$N$3:$N$5800,'CFT Main'!$C11,Work!$G$3:$G$5800,"Ongoing") -> 50 | AO11: =COUNTIFS(Work!$D$3:$D$5800,'CFT Main'!$B11,Work!$N$3:$N$5800,'CFT Main'!$C11,Work!$G$3:$G$5800,"*Completed") -> 20 | AP11: =COUNTIFS(Work!$D$3:$D$5800,'CFT Main'!$B11,Work!$N$3:$N$5800,'CFT Main'!$C11,Work!$G$3:$G$5800,"Ongoing",Work!$F$3:$F$5800,AP$5) -> 8 | AQ11: =COUNTIFS(Work!$D$3:$D$5800,'CFT Main'!$B11,Work!$N$3:$N$5800,'CFT Main'!$C11,Work!$G$3:$G$5800,"*Completed",Work!$F$3:$F$5800,AP$5) -> 4 | AR11: =COUNTIFS(Work!$D$3:$D$5800,'CFT Main'!$B11,Work!$N$3:$N$5800,'CFT Main'!$C11,Work!$G$3:$G$5800,"Ongoing",Work!$F$3:$F$5800,AR$5) -> 8 | AS11: =COUNTIFS(Work!$D$3:$D$5800,'CFT Main'!$B11,Work!$N$3:$N$5800,'CFT Main'!$C11,Work!$G$3:$G$5800,"*Completed",Work!$F$3:$F$5800,AR$5) -> 5 | AT11: =COUNTIFS(Work!$D$3:$D$5800,'CFT Main'!$B11,Work!$N$3:$N$5800,'CFT Main'!$C11,Work!$G$3:$G$5800,"Ongoing",Work!$F$3:$F$5800,AT$5) -> 0 | AU11: =COUNTIFS(Work!$D$3:$D$5800,'CFT Main'!$B11,Work!$N$3:$N$5800,'CFT Main'!$C11,Work!$G$3:$G$5800,"*Completed",Work!$F$3:$F$5800,AT$5) -> 9 | AV11: =COUNTIFS(Work!$D$3:$D$5800,'CFT Main'!$B11,Work!$N$3:$N$5800,'CFT Main'!$C11,Work!$G$3:$G$5800,"Ongoing",Work!$F$3:$F$5800,AV$5) -> 0 | AW11: =COUNTIFS(Work!$D$3:$D$5800,'CFT Main'!$B11,Work!$N$3:$N$5800,'CFT Main'!$C11,Work!$G$3:$G$5800,"*Completed",Work!$F$3:$F$5800,AV$5) -> 2 | AX11: =COUNTIFS(Work!$D$3:$D$5800,'CFT Main'!$B11,Work!$N$3:$N$5800,'CFT Main'!$C11,Work!$G$3:$G$5800,"Ongoing",Work!$F$3:$F$5800,AX$5) -> 0 | AY11: =COUNTIFS(Work!$D$3:$D$5800,'CFT Main'!$B11,Work!$N$3:$N$5800,'CFT Main'!$C11,Work!$G$3:$G$5800,"*Completed",Work!$F$3:$F$5800,AX$5) -> 0 | AZ11: =COUNTIFS(Work!$D$3:$D$5800,'CFT Main'!$B11,Work!$N$3:$N$5800,'CFT Main'!$C11,Work!$G$3:$G$5800,"Ongoing",Work!$F$3:$F$5800,AZ$5) -> 0 | BA11: =COUNTIFS(Work!$D$3:$D$5800,'CFT Main'!$B11,Work!$N$3:$N$5800,'CFT Main'!$C11,Work!$G$3:$G$5800,"*Completed",Work!$F$3:$F$5800,AZ$5) -> 0 | BB11: =COUNTIFS(Work!$D$3:$D$5800,'CFT Main'!$B11,Work!$N$3:$N$5800,'CFT Main'!$C11,Work!$G$3:$G$5800,"Ongoing",Work!$F$3:$F$5800,BB$5) -> 0 | BC11: =COUNTIFS(Work!$D$3:$D$5800,'CFT Main'!$B11,Work!$N$3:$N$5800,'CFT Main'!$C11,Work!$G$3:$G$5800,"*Completed",Work!$F$3:$F$5800,BB$5) -> 0 | BD11: =COUNTIFS(Work!$D$3:$D$5800,'CFT Main'!$B11,Work!$N$3:$N$5800,'CFT Main'!$C11,Work!$G$3:$G$5800,"Ongoing",Work!$F$3:$F$5800,BD$5) -> 34 | BE11: =COUNTIFS(Work!$D$3:$D$5800,'CFT Main'!$B11,Work!$N$3:$N$5800,'CFT Main'!$C11,Work!$G$3:$G$5800,"*Completed",Work!$F$3:$F$5800,BD$5) -> 0
A12: 6 | B12: AMARPATAN | C12: PARASWAHI | D12: AMAHAN | E12: अनिल पटेल अति0 | F12: Add. NIKHIL MISHRA | G12: =SUMIFS(#REF!,'GP Main'!$B$8:$B$827,'CFT Main'!$B10,'GP Main'!$C$8:$C$827,'CFT Main'!$C10) -> #REF! | H12: =SUMIFS(#REF!,'GP Main'!$B$8:$B$827,'CFT Main'!$B10,'GP Main'!$C$8:$C$827,'CFT Main'!$C10) -> #REF! | I12: =SUMIFS(#REF!,'GP Main'!$B$8:$B$827,'CFT Main'!$B10,'GP Main'!$C$8:$C$827,'CFT Main'!$C10) -> #REF! | J12: =SUMIFS(#REF!,'GP Main'!$B$8:$B$827,'CFT Main'!$B10,'GP Main'!$C$8:$C$827,'CFT Main'!$C10) -> #REF! | K12: =SUMIFS(#REF!,'GP Main'!$B$8:$B$827,'CFT Main'!$B10,'GP Main'!$C$8:$C$827,'CFT Main'!$C10) -> #REF! | L12: =SUMIFS(#REF!,'GP Main'!$B$8:$B$827,'CFT Main'!$B10,'GP Main'!$C$8:$C$827,'CFT Main'!$C10) -> #REF! | M12: =SUMIFS(#REF!,'GP Main'!$B$8:$B$827,'CFT Main'!$B10,'GP Main'!$C$8:$C$827,'CFT Main'!$C10) -> #REF! | N12: =SUMIFS(#REF!,'GP Main'!$B$8:$B$827,'CFT Main'!$B10,'GP Main'!$C$8:$C$827,'CFT Main'!$C10) -> #REF! | ... AB12: =SUMIFS(#REF!,'GP Main'!$B$8:$B$827,'CFT Main'!$B10,'GP Main'!$C$8:$C$827,'CFT Main'!$C10) -> #REF! | AD12: =SUMIFS(#REF!,'GP Main'!$B$8:$B$827,'CFT Main'!$B10,'GP Main'!$C$8:$C$827,'CFT Main'!$C10) -> #REF! | AE12: =SUMIFS(#REF!,'GP Main'!$B$8:$B$827,'CFT Main'!$B10,'GP Main'!$C$8:$C$827,'CFT Main'!$C10) -> #REF! | AG12: =SUMIFS(#REF!,'GP Main'!$B$8:$B$827,'CFT Main'!$B10,'GP Main'!$C$8:$C$827,'CFT Main'!$C10) -> #REF! | AH12: =SUMIFS(#REF!,'GP Main'!$B$8:$B$827,'CFT Main'!$B10,'GP Main'!$C$8:$C$827,'CFT Main'!$C10) -> #REF! | AI12: =SUMIFS(#REF!,'GP Main'!$B$8:$B$827,'CFT Main'!$B10,'GP Main'!$C$8:$C$827,'CFT Main'!$C10) -> #REF! | AJ12: =SUMIFS(#REF!,'GP Main'!$B$8:$B$827,'CFT Main'!$B10,'GP Main'!$C$8:$C$827,'CFT Main'!$C10) -> #REF! | AK12: =SUMIFS(#REF!,'GP Main'!$B$8:$B$827,'CFT Main'!$B10,'GP Main'!$C$8:$C$827,'CFT Main'!$C10) -> #REF! | AM12: भूपेन्द्र सिंह अति0 | AN12: =COUNTIFS(Work!$D$3:$D$5800,'CFT Main'!$B12,Work!$N$3:$N$5800,'CFT Main'!$C12,Work!$G$3:$G$5800,"Ongoing") -> 48 | AO12: =COUNTIFS(Work!$D$3:$D$5800,'CFT Main'!$B12,Work!$N$3:$N$5800,'CFT Main'!$C12,Work!$G$3:$G$5800,"*Completed") -> 27 | AP12: =COUNTIFS(Work!$D$3:$D$5800,'CFT Main'!$B12,Work!$N$3:$N$5800,'CFT Main'!$C12,Work!$G$3:$G$5800,"Ongoing",Work!$F$3:$F$5800,AP$5) -> 8 | AQ12: =COUNTIFS(Work!$D$3:$D$5800,'CFT Main'!$B12,Work!$N$3:$N$5800,'CFT Main'!$C12,Work!$G$3:$G$5800,"*Completed",Work!$F$3:$F$5800,AP$5) -> 4 | AR12: =COUNTIFS(Work!$D$3:$D$5800,'CFT Main'!$B12,Work!$N$3:$N$5800,'CFT Main'!$C12,Work!$G$3:$G$5800,"Ongoing",Work!$F$3:$F$5800,AR$5) -> 3 | AS12: =COUNTIFS(Work!$D$3:$D$5800,'CFT Main'!$B12,Work!$N$3:$N$5800,'CFT Main'!$C12,Work!$G$3:$G$5800,"*Completed",Work!$F$3:$F$5800,AR$5) -> 18 | AT12: =COUNTIFS(Work!$D$3:$D$5800,'CFT Main'!$B12,Work!$N$3:$N$5800,'CFT Main'!$C12,Work!$G$3:$G$5800,"Ongoing",Work!$F$3:$F$5800,AT$5) -> 0 | AU12: =COUNTIFS(Work!$D$3:$D$5800,'CFT Main'!$B12,Work!$N$3:$N$5800,'CFT Main'!$C12,Work!$G$3:$G$5800,"*Completed",Work!$F$3:$F$5800,AT$5) -> 5 | AV12: =COUNTIFS(Work!$D$3:$D$5800,'CFT Main'!$B12,Work!$N$3:$N$5800,'CFT Main'!$C12,Work!$G$3:$G$5800,"Ongoing",Work!$F$3:$F$5800,AV$5) -> 0 | AW12: =COUNTIFS(Work!$D$3:$D$5800,'CFT Main'!$B12,Work!$N$3:$N$5800,'CFT Main'!$C12,Work!$G$3:$G$5800,"*Completed",Work!$F$3:$F$5800,AV$5) -> 0 | AX12: =COUNTIFS(Work!$D$3:$D$5800,'CFT Main'!$B12,Work!$N$3:$N$5800,'CFT Main'!$C12,Work!$G$3:$G$5800,"Ongoing",Work!$F$3:$F$5800,AX$5) -> 0 | AY12: =COUNTIFS(Work!$D$3:$D$5800,'CFT Main'!$B12,Work!$N$3:$N$5800,'CFT Main'!$C12,Work!$G$3:$G$5800,"*Completed",Work!$F$3:$F$5800,AX$5) -> 0 | AZ12: =COUNTIFS(Work!$D$3:$D$5800,'CFT Main'!$B12,Work!$N$3:$N$5800,'CFT Main'!$C12,Work!$G$3:$G$5800,"Ongoing",Work!$F$3:$F$5800,AZ$5) -> 0 | BA12: =COUNTIFS(Work!$D$3:$D$5800,'CFT Main'!$B12,Work!$N$3:$N$5800,'CFT Main'!$C12,Work!$G$3:$G$5800,"*Completed",Work!$F$3:$F$5800,AZ$5) -> 0 | BB12: =COUNTIFS(Work!$D$3:$D$5800,'CFT Main'!$B12,Work!$N$3:$N$5800,'CFT Main'!$C12,Work!$G$3:$G$5800,"Ongoing",Work!$F$3:$F$5800,BB$5) -> 0 | BC12: =COUNTIFS(Work!$D$3:$D$5800,'CFT Main'!$B12,Work!$N$3:$N$5800,'CFT Main'!$C12,Work!$G$3:$G$5800,"*Completed",Work!$F$3:$F$5800,BB$5) -> 0 | BD12: =COUNTIFS(Work!$D$3:$D$5800,'CFT Main'!$B12,Work!$N$3:$N$5800,'CFT Main'!$C12,Work!$G$3:$G$5800,"Ongoing",Work!$F$3:$F$5800,BD$5) -> 37 | BE12: =COUNTIFS(Work!$D$3:$D$5800,'CFT Main'!$B12,Work!$N$3:$N$5800,'CFT Main'!$C12,Work!$G$3:$G$5800,"*Completed",Work!$F$3:$F$5800,BD$5) -> 0
A13: 7 | B13: MAIHAR | C13: BADERA | D13: AALAMGANJ | E13: धनंजय त्रिपाठी | F13: Add. NIKHIL MISHRA | G13: =SUMIFS(#REF!,'GP Main'!$B$8:$B$827,'CFT Main'!$B7,'GP Main'!$C$8:$C$827,'CFT Main'!$C7) -> #REF! | H13: =SUMIFS(#REF!,'GP Main'!$B$8:$B$827,'CFT Main'!$B7,'GP Main'!$C$8:$C$827,'CFT Main'!$C7) -> #REF! | I13: =SUMIFS(#REF!,'GP Main'!$B$8:$B$827,'CFT Main'!$B7,'GP Main'!$C$8:$C$827,'CFT Main'!$C7) -> #REF! | J13: =SUMIFS(#REF!,'GP Main'!$B$8:$B$827,'CFT Main'!$B7,'GP Main'!$C$8:$C$827,'CFT Main'!$C7) -> #REF! | K13: =SUMIFS(#REF!,'GP Main'!$B$8:$B$827,'CFT Main'!$B7,'GP Main'!$C$8:$C$827,'CFT Main'!$C7) -> #REF! | L13: =SUMIFS(#REF!,'GP Main'!$B$8:$B$827,'CFT Main'!$B7,'GP Main'!$C$8:$C$827,'CFT Main'!$C7) -> #REF! | M13: =SUMIFS(#REF!,'GP Main'!$B$8:$B$827,'CFT Main'!$B7,'GP Main'!$C$8:$C$827,'CFT Main'!$C7) -> #REF! | N13: =SUMIFS(#REF!,'GP Main'!$B$8:$B$827,'CFT Main'!$B7,'GP Main'!$C$8:$C$827,'CFT Main'!$C7) -> #REF! | ... AB13: =SUMIFS(#REF!,'GP Main'!$B$8:$B$827,'CFT Main'!$B7,'GP Main'!$C$8:$C$827,'CFT Main'!$C7) -> #REF! | AD13: =SUMIFS(#REF!,'GP Main'!$B$8:$B$827,'CFT Main'!$B7,'GP Main'!$C$8:$C$827,'CFT Main'!$C7) -> #REF! | AE13: =SUMIFS(#REF!,'GP Main'!$B$8:$B$827,'CFT Main'!$B7,'GP Main'!$C$8:$C$827,'CFT Main'!$C7) -> #REF! | AG13: =SUMIFS(#REF!,'GP Main'!$B$8:$B$827,'CFT Main'!$B7,'GP Main'!$C$8:$C$827,'CFT Main'!$C7) -> #REF! | AH13: =SUMIFS(#REF!,'GP Main'!$B$8:$B$827,'CFT Main'!$B7,'GP Main'!$C$8:$C$827,'CFT Main'!$C7) -> #REF! | AI13: =SUMIFS(#REF!,'GP Main'!$B$8:$B$827,'CFT Main'!$B7,'GP Main'!$C$8:$C$827,'CFT Main'!$C7) -> #REF! | AJ13: =SUMIFS(#REF!,'GP Main'!$B$8:$B$827,'CFT Main'!$B7,'GP Main'!$C$8:$C$827,'CFT Main'!$C7) -> #REF! | AK13: =SUMIFS(#REF!,'GP Main'!$B$8:$B$827,'CFT Main'!$B7,'GP Main'!$C$8:$C$827,'CFT Main'!$C7) -> #REF! | AM13: परितोष सिंह | AN13: =COUNTIFS(Work!$D$3:$D$5800,'CFT Main'!$B13,Work!$N$3:$N$5800,'CFT Main'!$C13,Work!$G$3:$G$5800,"Ongoing") -> 25 | AO13: =COUNTIFS(Work!$D$3:$D$5800,'CFT Main'!$B13,Work!$N$3:$N$5800,'CFT Main'!$C13,Work!$G$3:$G$5800,"*Completed") -> 46 | AP13: =COUNTIFS(Work!$D$3:$D$5800,'CFT Main'!$B13,Work!$N$3:$N$5800,'CFT Main'!$C13,Work!$G$3:$G$5800,"Ongoing",Work!$F$3:$F$5800,AP$5) -> 10 | AQ13: =COUNTIFS(Work!$D$3:$D$5800,'CFT Main'!$B13,Work!$N$3:$N$5800,'CFT Main'!$C13,Work!$G$3:$G$5800,"*Completed",Work!$F$3:$F$5800,AP$5) -> 12 | AR13: =COUNTIFS(Work!$D$3:$D$5800,'CFT Main'!$B13,Work!$N$3:$N$5800,'CFT Main'!$C13,Work!$G$3:$G$5800,"Ongoing",Work!$F$3:$F$5800,AR$5) -> 3 | AS13: =COUNTIFS(Work!$D$3:$D$5800,'CFT Main'!$B13,Work!$N$3:$N$5800,'CFT Main'!$C13,Work!$G$3:$G$5800,"*Completed",Work!$F$3:$F$5800,AR$5) -> 9 | AT13: =COUNTIFS(Work!$D$3:$D$5800,'CFT Main'!$B13,Work!$N$3:$N$5800,'CFT Main'!$C13,Work!$G$3:$G$5800,"Ongoing",Work!$F$3:$F$5800,AT$5) -> 2 | AU13: =COUNTIFS(Work!$D$3:$D$5800,'CFT Main'!$B13,Work!$N$3:$N$5800,'CFT Main'!$C13,Work!$G$3:$G$5800,"*Completed",Work!$F$3:$F$5800,AT$5) -> 12 | AV13: =COUNTIFS(Work!$D$3:$D$5800,'CFT Main'!$B13,Work!$N$3:$N$5800,'CFT Main'!$C13,Work!$G$3:$G$5800,"Ongoing",Work!$F$3:$F$5800,AV$5) -> 2 | AW13: =COUNTIFS(Work!$D$3:$D$5800,'CFT Main'!$B13,Work!$N$3:$N$5800,'CFT Main'!$C13,Work!$G$3:$G$5800,"*Completed",Work!$F$3:$F$5800,AV$5) -> 0 | AX13: =COUNTIFS(Work!$D$3:$D$5800,'CFT Main'!$B13,Work!$N$3:$N$5800,'CFT Main'!$C13,Work!$G$3:$G$5800,"Ongoing",Work!$F$3:$F$5800,AX$5) -> 0 | AY13: =COUNTIFS(Work!$D$3:$D$5800,'CFT Main'!$B13,Work!$N$3:$N$5800,'CFT Main'!$C13,Work!$G$3:$G$5800,"*Completed",Work!$F$3:$F$5800,AX$5) -> 13 | AZ13: =COUNTIFS(Work!$D$3:$D$5800,'CFT Main'!$B13,Work!$N$3:$N$5800,'CFT Main'!$C13,Work!$G$3:$G$5800,"Ongoing",Work!$F$3:$F$5800,AZ$5) -> 0 | BA13: =COUNTIFS(Work!$D$3:$D$5800,'CFT Main'!$B13,Work!$N$3:$N$5800,'CFT Main'!$C13,Work!$G$3:$G$5800,"*Completed",Work!$F$3:$F$5800,AZ$5) -> 0 | BB13: =COUNTIFS(Work!$D$3:$D$5800,'CFT Main'!$B13,Work!$N$3:$N$5800,'CFT Main'!$C13,Work!$G$3:$G$5800,"Ongoing",Work!$F$3:$F$5800,BB$5) -> 0 | BC13: =COUNTIFS(Work!$D$3:$D$5800,'CFT Main'!$B13,Work!$N$3:$N$5800,'CFT Main'!$C13,Work!$G$3:$G$5800,"*Completed",Work!$F$3:$F$5800,BB$5) -> 0 | BD13: =COUNTIFS(Work!$D$3:$D$5800,'CFT Main'!$B13,Work!$N$3:$N$5800,'CFT Main'!$C13,Work!$G$3:$G$5800,"Ongoing",Work!$F$3:$F$5800,BD$5) -> 8 | BE13: =COUNTIFS(Work!$D$3:$D$5800,'CFT Main'!$B13,Work!$N$3:$N$5800,'CFT Main'!$C13,Work!$G$3:$G$5800,"*Completed",Work!$F$3:$F$5800,BD$5) -> 0
A14: 8 | B14: MAIHAR | C14: AMDARA | D14: ANTARIYA | E14: बृजेश सिंह | F14: Add. RP Tripathi | G14: =SUMIFS(#REF!,'GP Main'!$B$8:$B$827,'CFT Main'!$B16,'GP Main'!$C$8:$C$827,'CFT Main'!$C16) -> #REF! | H14: =SUMIFS(#REF!,'GP Main'!$B$8:$B$827,'CFT Main'!$B16,'GP Main'!$C$8:$C$827,'CFT Main'!$C16) -> #REF! | I14: =SUMIFS(#REF!,'GP Main'!$B$8:$B$827,'CFT Main'!$B16,'GP Main'!$C$8:$C$827,'CFT Main'!$C16) -> #REF! | J14: =SUMIFS(#REF!,'GP Main'!$B$8:$B$827,'CFT Main'!$B16,'GP Main'!$C$8:$C$827,'CFT Main'!$C16) -> #REF! | K14: =SUMIFS(#REF!,'GP Main'!$B$8:$B$827,'CFT Main'!$B16,'GP Main'!$C$8:$C$827,'CFT Main'!$C16) -> #REF! | L14: =SUMIFS(#REF!,'GP Main'!$B$8:$B$827,'CFT Main'!$B16,'GP Main'!$C$8:$C$827,'CFT Main'!$C16) -> #REF! | M14: =SUMIFS(#REF!,'GP Main'!$B$8:$B$827,'CFT Main'!$B16,'GP Main'!$C$8:$C$827,'CFT Main'!$C16) -> #REF! | N14: =SUMIFS(#REF!,'GP Main'!$B$8:$B$827,'CFT Main'!$B16,'GP Main'!$C$8:$C$827,'CFT Main'!$C16) -> #REF! | ... AB14: =SUMIFS(#REF!,'GP Main'!$B$8:$B$827,'CFT Main'!$B16,'GP Main'!$C$8:$C$827,'CFT Main'!$C16) -> #REF! | AD14: =SUMIFS(#REF!,'GP Main'!$B$8:$B$827,'CFT Main'!$B16,'GP Main'!$C$8:$C$827,'CFT Main'!$C16) -> #REF! | AE14: =SUMIFS(#REF!,'GP Main'!$B$8:$B$827,'CFT Main'!$B16,'GP Main'!$C$8:$C$827,'CFT Main'!$C16) -> #REF! | AG14: =SUMIFS(#REF!,'GP Main'!$B$8:$B$827,'CFT Main'!$B16,'GP Main'!$C$8:$C$827,'CFT Main'!$C16) -> #REF! | AH14: =SUMIFS(#REF!,'GP Main'!$B$8:$B$827,'CFT Main'!$B16,'GP Main'!$C$8:$C$827,'CFT Main'!$C16) -> #REF! | AI14: =SUMIFS(#REF!,'GP Main'!$B$8:$B$827,'CFT Main'!$B16,'GP Main'!$C$8:$C$827,'CFT Main'!$C16) -> #REF! | AJ14: =SUMIFS(#REF!,'GP Main'!$B$8:$B$827,'CFT Main'!$B16,'GP Main'!$C$8:$C$827,'CFT Main'!$C16) -> #REF! | AK14: =SUMIFS(#REF!,'GP Main'!$B$8:$B$827,'CFT Main'!$B16,'GP Main'!$C$8:$C$827,'CFT Main'!$C16) -> #REF! | AM14: परितोष सिंह | AN14: =COUNTIFS(Work!$D$3:$D$5800,'CFT Main'!$B14,Work!$N$3:$N$5800,'CFT Main'!$C14,Work!$G$3:$G$5800,"Ongoing") -> 64 | AO14: =COUNTIFS(Work!$D$3:$D$5800,'CFT Main'!$B14,Work!$N$3:$N$5800,'CFT Main'!$C14,Work!$G$3:$G$5800,"*Completed") -> 72 | AP14: =COUNTIFS(Work!$D$3:$D$5800,'CFT Main'!$B14,Work!$N$3:$N$5800,'CFT Main'!$C14,Work!$G$3:$G$5800,"Ongoing",Work!$F$3:$F$5800,AP$5) -> 18 | AQ14: =COUNTIFS(Work!$D$3:$D$5800,'CFT Main'!$B14,Work!$N$3:$N$5800,'CFT Main'!$C14,Work!$G$3:$G$5800,"*Completed",Work!$F$3:$F$5800,AP$5) -> 20 | AR14: =COUNTIFS(Work!$D$3:$D$5800,'CFT Main'!$B14,Work!$N$3:$N$5800,'CFT Main'!$C14,Work!$G$3:$G$5800,"Ongoing",Work!$F$3:$F$5800,AR$5) -> 4 | AS14: =COUNTIFS(Work!$D$3:$D$5800,'CFT Main'!$B14,Work!$N$3:$N$5800,'CFT Main'!$C14,Work!$G$3:$G$5800,"*Completed",Work!$F$3:$F$5800,AR$5) -> 19 | AT14: =COUNTIFS(Work!$D$3:$D$5800,'CFT Main'!$B14,Work!$N$3:$N$5800,'CFT Main'!$C14,Work!$G$3:$G$5800,"Ongoing",Work!$F$3:$F$5800,AT$5) -> 2 | AU14: =COUNTIFS(Work!$D$3:$D$5800,'CFT Main'!$B14,Work!$N$3:$N$5800,'CFT Main'!$C14,Work!$G$3:$G$5800,"*Completed",Work!$F$3:$F$5800,AT$5) -> 15 | AV14: =COUNTIFS(Work!$D$3:$D$5800,'CFT Main'!$B14,Work!$N$3:$N$5800,'CFT Main'!$C14,Work!$G$3:$G$5800,"Ongoing",Work!$F$3:$F$5800,AV$5) -> 2 | AW14: =COUNTIFS(Work!$D$3:$D$5800,'CFT Main'!$B14,Work!$N$3:$N$5800,'CFT Main'!$C14,Work!$G$3:$G$5800,"*Completed",Work!$F$3:$F$5800,AV$5) -> 3 | AX14: =COUNTIFS(Work!$D$3:$D$5800,'CFT Main'!$B14,Work!$N$3:$N$5800,'CFT Main'!$C14,Work!$G$3:$G$5800,"Ongoing",Work!$F$3:$F$5800,AX$5) -> 6 | AY14: =COUNTIFS(Work!$D$3:$D$5800,'CFT Main'!$B14,Work!$N$3:$N$5800,'CFT Main'!$C14,Work!$G$3:$G$5800,"*Completed",Work!$F$3:$F$5800,AX$5) -> 15 | AZ14: =COUNTIFS(Work!$D$3:$D$5800,'CFT Main'!$B14,Work!$N$3:$N$5800,'CFT Main'!$C14,Work!$G$3:$G$5800,"Ongoing",Work!$F$3:$F$5800,AZ$5) -> 0 | BA14: =COUNTIFS(Work!$D$3:$D$5800,'CFT Main'!$B14,Work!$N$3:$N$5800,'CFT Main'!$C14,Work!$G$3:$G$5800,"*Completed",Work!$F$3:$F$5800,AZ$5) -> 0 | BB14: =COUNTIFS(Work!$D$3:$D$5800,'CFT Main'!$B14,Work!$N$3:$N$5800,'CFT Main'!$C14,Work!$G$3:$G$5800,"Ongoing",Work!$F$3:$F$5800,BB$5) -> 2 | BC14: =COUNTIFS(Work!$D$3:$D$5800,'CFT Main'!$B14,Work!$N$3:$N$5800,'CFT Main'!$C14,Work!$G$3:$G$5800,"*Completed",Work!$F$3:$F$5800,BB$5) -> 0 | BD14: =COUNTIFS(Work!$D$3:$D$5800,'CFT Main'!$B14,Work!$N$3:$N$5800,'CFT Main'!$C14,Work!$G$3:$G$5800,"Ongoing",Work!$F$3:$F$5800,BD$5) -> 30 | BE14: =COUNTIFS(Work!$D$3:$D$5800,'CFT Main'!$B14,Work!$N$3:$N$5800,'CFT Main'!$C14,Work!$G$3:$G$5800,"*Completed",Work!$F$3:$F$5800,BD$5) -> 0
A15: 9 | B15: MAIHAR | C15: TILAURA | D15: BAHUTI | E15: राजा भैया सिंह | F15: Add. RP Tripathi | G15: =SUMIFS(#REF!,'GP Main'!$B$8:$B$827,'CFT Main'!$B19,'GP Main'!$C$8:$C$827,'CFT Main'!$C19) -> #REF! | H15: =SUMIFS(#REF!,'GP Main'!$B$8:$B$827,'CFT Main'!$B19,'GP Main'!$C$8:$C$827,'CFT Main'!$C19) -> #REF! | I15: =SUMIFS(#REF!,'GP Main'!$B$8:$B$827,'CFT Main'!$B19,'GP Main'!$C$8:$C$827,'CFT Main'!$C19) -> #REF! | J15: =SUMIFS(#REF!,'GP Main'!$B$8:$B$827,'CFT Main'!$B19,'GP Main'!$C$8:$C$827,'CFT Main'!$C19) -> #REF! | K15: =SUMIFS(#REF!,'GP Main'!$B$8:$B$827,'CFT Main'!$B19,'GP Main'!$C$8:$C$827,'CFT Main'!$C19) -> #REF! | L15: =SUMIFS(#REF!,'GP Main'!$B$8:$B$827,'CFT Main'!$B19,'GP Main'!$C$8:$C$827,'CFT Main'!$C19) -> #REF! | M15: =SUMIFS(#REF!,'GP Main'!$B$8:$B$827,'CFT Main'!$B19,'GP Main'!$C$8:$C$827,'CFT Main'!$C19) -> #REF! | N15: =SUMIFS(#REF!,'GP Main'!$B$8:$B$827,'CFT Main'!$B19,'GP Main'!$C$8:$C$827,'CFT Main'!$C19) -> #REF! | ... AB15: =SUMIFS(#REF!,'GP Main'!$B$8:$B$827,'CFT Main'!$B19,'GP Main'!$C$8:$C$827,'CFT Main'!$C19) -> #REF! | AD15: =SUMIFS(#REF!,'GP Main'!$B$8:$B$827,'CFT Main'!$B19,'GP Main'!$C$8:$C$827,'CFT Main'!$C19) -> #REF! | AE15: =SUMIFS(#REF!,'GP Main'!$B$8:$B$827,'CFT Main'!$B19,'GP Main'!$C$8:$C$827,'CFT Main'!$C19) -> #REF! | AG15: =SUMIFS(#REF!,'GP Main'!$B$8:$B$827,'CFT Main'!$B19,'GP Main'!$C$8:$C$827,'CFT Main'!$C19) -> #REF! | AH15: =SUMIFS(#REF!,'GP Main'!$B$8:$B$827,'CFT Main'!$B19,'GP Main'!$C$8:$C$827,'CFT Main'!$C19) -> #REF! | AI15: =SUMIFS(#REF!,'GP Main'!$B$8:$B$827,'CFT Main'!$B19,'GP Main'!$C$8:$C$827,'CFT Main'!$C19) -> #REF! | AJ15: =SUMIFS(#REF!,'GP Main'!$B$8:$B$827,'CFT Main'!$B19,'GP Main'!$C$8:$C$827,'CFT Main'!$C19) -> #REF! | AK15: =SUMIFS(#REF!,'GP Main'!$B$8:$B$827,'CFT Main'!$B19,'GP Main'!$C$8:$C$827,'CFT Main'!$C19) -> #REF! | AM15: परितोष सिंह | AN15: =COUNTIFS(Work!$D$3:$D$5800,'CFT Main'!$B15,Work!$N$3:$N$5800,'CFT Main'!$C15,Work!$G$3:$G$5800,"Ongoing") -> 40 | AO15: =COUNTIFS(Work!$D$3:$D$5800,'CFT Main'!$B15,Work!$N$3:$N$5800,'CFT Main'!$C15,Work!$G$3:$G$5800,"*Completed") -> 51 | AP15: =COUNTIFS(Work!$D$3:$D$5800,'CFT Main'!$B15,Work!$N$3:$N$5800,'CFT Main'!$C15,Work!$G$3:$G$5800,"Ongoing",Work!$F$3:$F$5800,AP$5) -> 21 | AQ15: =COUNTIFS(Work!$D$3:$D$5800,'CFT Main'!$B15,Work!$N$3:$N$5800,'CFT Main'!$C15,Work!$G$3:$G$5800,"*Completed",Work!$F$3:$F$5800,AP$5) -> 30 | AR15: =COUNTIFS(Work!$D$3:$D$5800,'CFT Main'!$B15,Work!$N$3:$N$5800,'CFT Main'!$C15,Work!$G$3:$G$5800,"Ongoing",Work!$F$3:$F$5800,AR$5) -> 1 | AS15: =COUNTIFS(Work!$D$3:$D$5800,'CFT Main'!$B15,Work!$N$3:$N$5800,'CFT Main'!$C15,Work!$G$3:$G$5800,"*Completed",Work!$F$3:$F$5800,AR$5) -> 17 | AT15: =COUNTIFS(Work!$D$3:$D$5800,'CFT Main'!$B15,Work!$N$3:$N$5800,'CFT Main'!$C15,Work!$G$3:$G$5800,"Ongoing",Work!$F$3:$F$5800,AT$5) -> 0 | AU15: =COUNTIFS(Work!$D$3:$D$5800,'CFT Main'!$B15,Work!$N$3:$N$5800,'CFT Main'!$C15,Work!$G$3:$G$5800,"*Completed",Work!$F$3:$F$5800,AT$5) -> 3 | AV15: =COUNTIFS(Work!$D$3:$D$5800,'CFT Main'!$B15,Work!$N$3:$N$5800,'CFT Main'!$C15,Work!$G$3:$G$5800,"Ongoing",Work!$F$3:$F$5800,AV$5) -> 3 | AW15: =COUNTIFS(Work!$D$3:$D$5800,'CFT Main'!$B15,Work!$N$3:$N$5800,'CFT Main'!$C15,Work!$G$3:$G$5800,"*Completed",Work!$F$3:$F$5800,AV$5) -> 1 | AX15: =COUNTIFS(Work!$D$3:$D$5800,'CFT Main'!$B15,Work!$N$3:$N$5800,'CFT Main'!$C15,Work!$G$3:$G$5800,"Ongoing",Work!$F$3:$F$5800,AX$5) -> 0 | AY15: =COUNTIFS(Work!$D$3:$D$5800,'CFT Main'!$B15,Work!$N$3:$N$5800,'CFT Main'!$C15,Work!$G$3:$G$5800,"*Completed",Work!$F$3:$F$5800,AX$5) -> 0 | AZ15: =COUNTIFS(Work!$D$3:$D$5800,'CFT Main'!$B15,Work!$N$3:$N$5800,'CFT Main'!$C15,Work!$G$3:$G$5800,"Ongoing",Work!$F$3:$F$5800,AZ$5) -> 0 | BA15: =COUNTIFS(Work!$D$3:$D$5800,'CFT Main'!$B15,Work!$N$3:$N$5800,'CFT Main'!$C15,Work!$G$3:$G$5800,"*Completed",Work!$F$3:$F$5800,AZ$5) -> 0 | BB15: =COUNTIFS(Work!$D$3:$D$5800,'CFT Main'!$B15,Work!$N$3:$N$5800,'CFT Main'!$C15,Work!$G$3:$G$5800,"Ongoing",Work!$F$3:$F$5800,BB$5) -> 0 | BC15: =COUNTIFS(Work!$D$3:$D$5800,'CFT Main'!$B15,Work!$N$3:$N$5800,'CFT Main'!$C15,Work!$G$3:$G$5800,"*Completed",Work!$F$3:$F$5800,BB$5) -> 0 | BD15: =COUNTIFS(Work!$D$3:$D$5800,'CFT Main'!$B15,Work!$N$3:$N$5800,'CFT Main'!$C15,Work!$G$3:$G$5800,"Ongoing",Work!$F$3:$F$5800,BD$5) -> 15 | BE15: =COUNTIFS(Work!$D$3:$D$5800,'CFT Main'!$B15,Work!$N$3:$N$5800,'CFT Main'!$C15,Work!$G$3:$G$5800,"*Completed",Work!$F$3:$F$5800,BD$5) -> 0
